Workbook

Sheet Inputs
A1: SOURCES & USES MODEL — INPUTS
A2: Hypothetical M&A deal: Kotak Mahindra Bank (Acquirer) acquires IDFC First Bank (Target) | All financials in ₹ Crore | FY2026 actuals
A3: 🔵 Blue = typed input 🟢 Green = calculated formula 🟣 Purple = live price via Power Query (Data → Refresh All)
A5: ① ACQUIRER — KOTAK MAHINDRA BANK LTD (NSE: KOTAKBANK)
A6: Acquirer Net Profit, FY2026 (₹ Cr) | B6: 19288 | C6: Source: Kotak Q4FY26 results (consolidated), May 2026
A7: Acquirer Shares Outstanding (Crore shares) | B7: 198.86 | C7: Source: NSE / Kotak investor relations, FY2026
A8: Acquirer Current Share Price (₹) [LIVE — refreshes from NSE via Yahoo Finance] | B8: =IFERROR(acquirerliveprice,2050) -> 2050 | C8: Power Query named range: AcquirerLivePrice | Fallback: ₹2,050 if offline
A9: Acquirer Cash & Equivalents (₹ Cr) | B9: 12500 | C9: Approximate liquid reserves; adjust from latest balance sheet
A10: Acquirer Pre-Provision Operating Profit / PPOP (₹ Cr) | B10: 24800 | C10: Bank proxy for EBITDA — Kotak FY2026 estimate
A11: Acquirer Existing Net Borrowings (₹ Cr) | B11: 185000 | C11: Net borrowings (bonds, sub-debt, refinance) excl. deposits
A13: ② TARGET — IDFC FIRST BANK LTD (NSE: IDFCFIRSTB)
A14: Target Net Profit, FY2026 (₹ Cr) | B14: 1636 | C14: Source: IDFC First Bank Q4FY26 standalone results, Apr 2026
A15: Target Shares Outstanding (Crore shares) | B15: 860.83 | C15: Source: IDFC First Bank ESOS filing, May 2026
A16: Target Current Share Price (₹) [LIVE — refreshes from NSE via Yahoo Finance] | B16: =IFERROR(targetliveprice,68.5) -> 68.5 | C16: Power Query named range: TargetLivePrice | Fallback: ₹68.50 if offline
A17: Target PPOP / Pre-Provision Operating Profit (₹ Cr) | B17: 4800 | C17: IDFC First Bank FY2026 estimate (HSBC research)
A18: Target Existing Net Borrowings (₹ Cr) | B18: 48354 | C18: Source: IDFC First Bank Q3FY26 investor presentation (borrowings)
A20: ③ DEAL STRUCTURE
A21: Offer Premium to Target Current Market Price (%) | B21: 0.3 | C21: Typical Indian bank M&A premium range: 20–40%
A22: Offer Price per Target Share (₹) [calculated] | B22: =B16*(1+B21) -> 89.05 | C22: Offer price = Target live price × (1 + premium)
A23: Equity Purchase Price (₹ Cr) [calculated — live price × shares × (1+premium)] | B23: =B22*B15 -> 76656.912 | C23: Equity purchase price = Offer price × shares outstanding
A24: % Consideration paid in Cash | B24: 0.6 | C24: Adjust: 100% cash = all debt/BS-cash funded; 0% = all stock swap
A25: % Consideration paid in Stock [calculated] | B25: =1-B24 -> 0.4
A26: % of Cash portion funded by New Debt | B26: 0.7 | C26: RBI-regulated; typical for Indian bank acquisitions
A27: % of Cash portion funded by Balance-Sheet Cash [calculated] | B27: =1-B26 -> 0.3
A28: New Debt Interest Rate (% p.a.) | B28: 0.075 | C28: Approx. Indian bond/NCD rate, Jul 2026 environment
A29: Foregone Yield on Cash Used (% p.a.) | B29: 0.065 | C29: Opportunity cost of using balance-sheet cash (T-bill / liquid fund rate)
A30: Acquirer Effective Tax Rate (%) | B30: 0.2517 | C30: New domestic tax regime for large Indian banks, FY2026
A31: Integration / Transaction Costs (₹ Cr) | B31: 850 | C31: Advisory, stamp duty, tech integration, branch rationalisation
A33: ④ SYNERGIES
A34: Run-Rate Annual Synergies (₹ Cr, pre-tax) | B34: 2200 | C34: Cost + revenue synergies: branch overlap, funding cost, cross-sell
A35: Synergy Ramp — Year 1 (% of run-rate) | B35: 0.15
A36: Synergy Ramp — Year 2 (% of run-rate) | B36: 0.4
A37: Synergy Ramp — Year 3 (% of run-rate) | B37: 0.7
A38: Synergy Ramp — Year 4 (% of run-rate) | B38: 0.9
A39: Synergy Ramp — Year 5 (% of run-rate) | B39: 1
A41: ⑤ LEVERAGE & COVENANT (RBI-STYLE)
A42: Net Borrowings / PPOP Covenant Threshold (x) | B42: 8 | C42: Indicative internal threshold; RBI monitors leverage via CRAR separately

Sheet Calculations
A1: CALCULATIONS — PRO FORMA ACCRETION / DILUTION ANALYSIS
A2: Kotak Mahindra Bank (Acquirer) acquires IDFC First Bank (Target) | All values in ₹ Crore | Formulas reference Inputs tab — change any input and this sheet recalculates
A4: A · DEAL SIZE MECHANICS
A5: Equity Purchase Price (₹ Cr) | B5: =Inputs!B23 -> 76656.912
A6: Cash Consideration (₹ Cr) | B6: =Inputs!B23*Inputs!B24 -> 45994.147
A7: Stock Consideration (₹ Cr) | B7: =Inputs!B23*Inputs!B25 -> 30662.765
A8: New Debt Raised (₹ Cr) | B8: =Calculations!B6*Inputs!B26 -> 32195.903
A9: Balance-Sheet Cash Used (₹ Cr) | B9: =Calculations!B6*Inputs!B27 -> 13798.244
A10: New Shares Issued to Target Shareholders (Crore shares) | B10: =Calculations!B7/Inputs!B8 -> 14.957446
A11: Pro Forma Shares Outstanding (Crore shares) | B11: =Inputs!B7+Calculations!B10 -> 213.81745
A13: B · ANNUAL FINANCING COST IMPACT (after-tax, ₹ Cr)
A14: Incremental Interest on New Debt — pre-tax (₹ Cr) | B14: =Calculations!B8*Inputs!B28 -> 2414.6927
A15: Incremental Interest on New Debt — after-tax (₹ Cr) | B15: =Calculations!B14*(1-Inputs!B30) -> 1806.9146
A16: Foregone Yield on Cash Used — pre-tax (₹ Cr) | B16: =Calculations!B9*Inputs!B29 -> 896.88586
A17: Foregone Yield on Cash Used — after-tax (₹ Cr) | B17: =Calculations!B16*(1-Inputs!B30) -> 671.13969
A18: Total Annual Financing Drag — after-tax (₹ Cr) | B18: =Calculations!B15+Calculations!B17 -> 2478.0542
A20: C · AFTER-TAX SYNERGY SCHEDULE (₹ Cr)
B21: Year 1 | C21: Year 2 | D21: Year 3 | E21: Year 4 | F21: Year 5
A22: Synergy Ramp (% of run-rate) | B22: =Inputs!B35 -> 0.15 | C22: =Inputs!B36 -> 0.4 | D22: =Inputs!B37 -> 0.7 | E22: =Inputs!B38 -> 0.9 | F22: =Inputs!B39 -> 1
A23: Pre-Tax Synergies (₹ Cr) | B23: =Inputs!B34*Inputs!B35 -> 330 | C23: =Inputs!B34*Inputs!B36 -> 880 | D23: =Inputs!B34*Inputs!B37 -> 1540 | E23: =Inputs!B34*Inputs!B38 -> 1980 | F23: =Inputs!B34*Inputs!B39 -> 2200
A24: After-Tax Synergies (₹ Cr) | B24: =Calculations!B23*(1-Inputs!B30) -> 246.939 | C24: =Calculations!C23*(1-Inputs!B30) -> 658.504 | D24: =Calculations!D23*(1-Inputs!B30) -> 1152.382 | E24: =Calculations!E23*(1-Inputs!B30) -> 1481.634 | F24: =Calculations!F23*(1-Inputs!B30) -> 1646.26
A26: D · PRO FORMA NET PROFIT BUILD (₹ Cr)
B27: Year 1 | C27: Year 2 | D27: Year 3 | E27: Year 4 | F27: Year 5
A28: (+) Acquirer Standalone Net Profit (₹ Cr) | B28: =Inputs!B6 -> 19288 | C28: =Inputs!B6 -> 19288 | D28: =Inputs!B6 -> 19288 | E28: =Inputs!B6 -> 19288 | F28: =Inputs!B6 -> 19288
A29: (+) Target Net Profit (₹ Cr) | B29: =Inputs!B14 -> 1636 | C29: =Inputs!B14 -> 1636 | D29: =Inputs!B14 -> 1636 | E29: =Inputs!B14 -> 1636 | F29: =Inputs!B14 -> 1636
A30: (+) After-Tax Synergies (₹ Cr) | B30: =Calculations!B24 -> 246.939 | C30: =Calculations!C24 -> 658.504 | D30: =Calculations!D24 -> 1152.382 | E30: =Calculations!E24 -> 1481.634 | F30: =Calculations!F24 -> 1646.26
A31: (−) After-Tax Financing Drag (₹ Cr) | B31: =Calculations!B18 -> 2478.0542 | C31: =Calculations!B18 -> 2478.0542 | D31: =Calculations!B18 -> 2478.0542 | E31: =Calculations!B18 -> 2478.0542 | F31: =Calculations!B18 -> 2478.0542
A32: Pro Forma Net Profit (₹ Cr) | B32: =Calculations!B28+Calculations!B29+Calculations!B30-Calculations!B31 -> 18692.885 | C32: =Calculations!C28+Calculations!C29+Calculations!C30-Calculations!C31 -> 19104.45 | D32: =Calculations!D28+Calculations!D29+Calculations!D30-Calculations!D31 -> 19598.328 | E32: =Calculations!E28+Calculations!E29+Calculations!E30-Calculations!E31 -> 19927.58 | F32: =Calculations!F28+Calculations!F29+Calculations!F30-Calculations!F31 -> 20092.206
A34: E · EPS BRIDGE & ACCRETION / DILUTION
B35: Standalone | C35: Year 1 | D35: Year 2 | E35: Year 3 | F35: Year 4 | G35: Year 5
A36: Net Profit (₹ Cr) | B36: =Inputs!B6 -> 19288 | C36: =Calculations!B32 -> 18692.885 | D36: =Calculations!C32 -> 19104.45 | E36: =Calculations!D32 -> 19598.328 | F36: =Calculations!E32 -> 19927.58 | G36: =Calculations!F32 -> 20092.206
A37: Shares Outstanding (Crore) | B37: =Inputs!B7 -> 198.86 | C37: =Calculations!B11 -> 213.81745 | D37: =Calculations!B11 -> 213.81745 | E37: =Calculations!B11 -> 213.81745 | F37: =Calculations!B11 -> 213.81745 | G37: =Calculations!B11 -> 213.81745
A38: EPS (₹ per share) | B38: =Calculations!B36/(Inputs!B7*100) -> 0.96992859 | C38: =Calculations!B32/(Calculations!B11*100) -> 0.87424507 | D38: =Calculations!C32/(Calculations!B11*100) -> 0.8934935 | E38: =Calculations!D32/(Calculations!B11*100) -> 0.91659161 | F38: =Calculations!E32/(Calculations!B11*100) -> 0.93199035 | G38: =Calculations!F32/(Calculations!B11*100) -> 0.93968973
A39: Accretion / (Dilution) — ₹ per share | B39: — | C39: =Calculations!C38-Calculations!B38 -> -0.095683526 | D39: =Calculations!D38-Calculations!B38 -> -0.076435097 | E39: =Calculations!E38-Calculations!B38 -> -0.053336982 | F39: =Calculations!F38-Calculations!B38 -> -0.037938238 | G39: =Calculations!G38-Calculations!B38 -> -0.030238866
A40: Accretion / (Dilution) — % of Standalone EPS | B40: — | C40: =(Calculations!C38-Calculations!B38)/Calculations!B38 -> -0.098650073 | D40: =(Calculations!D38-Calculations!B38)/Calculations!B38 -> -0.07880487 | E40: =(Calculations!E38-Calculations!B38)/Calculations!B38 -> -0.054990627 | F40: =(Calculations!F38-Calculations!B38)/Calculations!B38 -> -0.039114465 | G40: =(Calculations!G38-Calculations!B38)/Calculations!B38 -> -0.031176384
A42: F · OUTPUT RANGE — Power BI & Tableau connect to this block (named range: OutputTable)
A43: Metric | B43: Standalone | C43: Year 1 | D43: Year 2 | E43: Year 3 | F43: Year 4 | G43: Year 5
A44: Acquirer Standalone Net Profit (₹ Cr) | B44: =Inputs!B6 -> 19288 | C44: =Inputs!B6 -> 19288 | D44: =Inputs!B6 -> 19288 | E44: =Inputs!B6 -> 19288 | F44: =Inputs!B6 -> 19288 | G44: =Inputs!B6 -> 19288
A45: Target Net Profit (₹ Cr) | B45: =Inputs!B14 -> 1636 | C45: =Inputs!B14 -> 1636 | D45: =Inputs!B14 -> 1636 | E45: =Inputs!B14 -> 1636 | F45: =Inputs!B14 -> 1636 | G45: =Inputs!B14 -> 1636
A46: After-Tax Synergies (₹ Cr) | B46: — | C46: =Calculations!B24 -> 246.939 | D46: =Calculations!C24 -> 658.504 | E46: =Calculations!D24 -> 1152.382 | F46: =Calculations!E24 -> 1481.634 | G46: =Calculations!F24 -> 1646.26
...

Sheet Sources & Uses
B3: SOURCES & USES OF FUNDS — ILLUSTRATIVE TRANSACTION ANALYSIS
B4: Kotak Mahindra Bank Ltd (Acquirer) × IDFC First Bank Ltd (Target)
B5: All figures in ₹ Crore | FY2026 actuals | Hypothetical / Illustrative only | E5: Deal structure reflects Inputs tab assumptions — updates automatically
B7: USES OF FUNDS | E7: SOURCES OF FUNDS
B8: Equity Purchase Price | C8: =Inputs!B23 -> 76656.912 | E8: New Debt Raised | F8: =Calculations!B8 -> 32195.903
B9: ↳ Cash Consideration | C9: =Calculations!B6 -> 45994.147 | E9: Balance-Sheet Cash Used | F9: =Calculations!B9 -> 13798.244
B10: ↳ Stock Consideration (at Kotak share price) | C10: =Calculations!B7 -> 30662.765 | E10: New Equity Issued (Stock Consideration) | F10: =Calculations!B7 -> 30662.765
B11: Control Premium Paid (above target market cap) | C11: =Inputs!B23*Inputs!B21/(1+Inputs!B21) -> 17690.056 | E11: Integration Costs (funded from cash / debt) | F11: =Inputs!B31 -> 850
B12: Integration & Transaction Costs | C12: =Inputs!B31 -> 850
B14: TOTAL USES | C14: =Inputs!B23+Inputs!B31 -> 77506.912 | E14: TOTAL SOURCES | F14: =Calculations!B8+Calculations!B9+Calculations!B7+Inputs!B31 -> 77506.912
B16: CHECK — Sources minus Uses (must equal zero) | E16: Sources − Uses = | F16: =F14-C14 -> 0
E17: ✔ Green = balanced | ✘ Red = sources ≠ uses (check inputs)
B20: KEY DEAL METRICS — DERIVED FROM INPUTS
B21: Offer Price per Share | C21: Offer Premium | D21: % Cash | E21: % Stock | F21: New Shares Issued (Cr)
B22: =Inputs!B22 -> 89.05 | C22: =Inputs!B21 -> 0.3 | D22: =Inputs!B24 -> 0.6 | E22: =Inputs!B25 -> 0.4 | F22: =Calculations!B10 -> 14.957446
B24: STRICTLY CONFIDENTIAL — FOR ILLUSTRATIVE & EDUCATIONAL PURPOSES ONLY | NOT FOR DISTRIBUTION | Sources & Uses — An Integrated M&A Decision Platform

Sheet Sensitivity
B1: SENSITIVITY ANALYSIS — YEAR 1 & YEAR 3 ACCRETION / (DILUTION) %
B2: Axes: Offer Premium % (rows, 15%→45%) × Cash Consideration % (cols, 0%→100%) | 🟡 = current Inputs assumption | Green = accretive | Red = dilutive
B4: TABLE 1 — YEAR 1 ACCRETION / (DILUTION) %
B5: Row input: Offer Premium | Column input: % Cash Consideration | Formula independent — no Excel Data Table engine required
B6: Premium ↓ / Cash % → | C6: 0 | D6: 0.1 | E6: 0.2 | F6: 0.3 | G6: 0.4 | H6: 0.5 | I6: 0.6 | J6: 0.7 | K6: 0.8 | L6: 0.9 | M6: 1
B7: 0.15 | C7: =(((Inputs!B6+Inputs!B14+(Inputs!B34*Inputs!B35*(1-Inputs!B30))-(((Inputs!B16*(1+0.15)*Inputs!B15)*0*Inputs!B26*Inputs!B28+(Inputs!B16*(1+0.15)*Inputs!B15)*0*Inputs!B27*Inputs!B29)*(1-Inputs!B30)))/((Inputs!B7+((Inputs!B16*(1+0.15)*Inputs!B15)*(1-0)/Inputs!B8))*100))-(Inputs!B6/(Inputs!B7*100)))/(Inputs!B6/(Inputs!B7*100)) -> -0.058919793 | D7: =(((Inputs!B6+Inputs!B14+(Inputs!B34*Inputs!B35*(1-Inputs!B30))-(((Inputs!B16*(1+0.15)*Inputs!B15)*0.1*Inputs!B26*Inputs!B28+(Inputs!B16*(1+0.15)*Inputs!B15)*0.1*Inputs!B27*Inputs!B29)*(1-Inputs!B30)))/((Inputs!B7+((Inputs!B16*(1+0.15)*Inputs!B15)*(1-0.1)/Inputs!B8))*100))-(Inputs!B6/(Inputs!B7*100)))/(Inputs!B6/(Inputs!B7*100)) -> -0.061779505 | E7: =(((Inputs!B6+Inputs!B14+(Inputs!B34*Inputs!B35*(1-Inputs!B30))-(((Inputs!B16*(1+0.15)*Inputs!B15)*0.2*Inputs!B26*Inputs!B28+(Inputs!B16*(1+0.15)*Inputs!B15)*0.2*Inputs!B27*Inputs!B29)*(1-Inputs!B30)))/((Inputs!B7+((Inputs!B16*(1+0.15)*Inputs!B15)*(1-0.2)/Inputs!B8))*100))-(Inputs!B6/(Inputs!B7*100)))/(Inputs!B6/(Inputs!B7*100)) -> -0.064723181 | F7: =(((Inputs!B6+Inputs!B14+(Inputs!B34*Inputs!B35*(1-Inputs!B30))-(((Inputs!B16*(1+0.15)*Inputs!B15)*0.3*Inputs!B26*Inputs!B28+(Inputs!B16*(1+0.15)*Inputs!B15)*0.3*Inputs!B27*Inputs!B29)*(1-Inputs!B30)))/((Inputs!B7+((Inputs!B16*(1+0.15)*Inputs!B15)*(1-0.3)/Inputs!B8))*100))-(Inputs!B6/(Inputs!B7*100)))/(Inputs!B6/(Inputs!B7*100)) -> -0.067754575 | G7: =(((Inputs!B6+Inputs!B14+(Inputs!B34*Inputs!B35*(1-Inputs!B30))-(((Inputs!B16*(1+0.15)*Inputs!B15)*0.4*Inputs!B26*Inputs!B28+(Inputs!B16*(1+0.15)*Inputs!B15)*0.4*Inputs!B27*Inputs!B29)*(1-Inputs!B30)))/((Inputs!B7+((Inputs!B16*(1+0.15)*Inputs!B15)*(1-0.4)/Inputs!B8))*100))-(Inputs!B6/(Inputs!B7*100)))/(Inputs!B6/(Inputs!B7*100)) -> -0.070877667 | H7: =(((Inputs!B6+Inputs!B14+(Inputs!B34*Inputs!B35*(1-Inputs!B30))-(((Inputs!B16*(1+0.15)*Inputs!B15)*0.5*Inputs!B26*Inputs!B28+(Inputs!B16*(1+0.15)*Inputs!B15)*0.5*Inputs!B27*Inputs!B29)*(1-Inputs!B30)))/((Inputs!B7+((Inputs!B16*(1+0.15)*Inputs!B15)*(1-0.5)/Inputs!B8))*100))-(Inputs!B6/(Inputs!B7*100)))/(Inputs!B6/(Inputs!B7*100)) -> -0.074096682 | I7: =(((Inputs!B6+Inputs!B14+(Inputs!B34*Inputs!B35*(1-Inputs!B30))-(((Inputs!B16*(1+0.15)*Inputs!B15)*0.6*Inputs!B26*Inputs!B28+(Inputs!B16*(1+0.15)*Inputs!B15)*0.6*Inputs!B27*Inputs!B29)*(1-Inputs!B30)))/((Inputs!B7+((Inputs!B16*(1+0.15)*Inputs!B15)*(1-0.6)/Inputs!B8))*100))-(Inputs!B6/(Inputs!B7*100)))/(Inputs!B6/(Inputs!B7*100)) -> -0.077416108 | J7: =(((Inputs!B6+Inputs!B14+(Inputs!B34*Inputs!B35*(1-Inputs!B30))-(((Inputs!B16*(1+0.15)*Inputs!B15)*0.7*Inputs!B26*Inputs!B28+(Inputs!B16*(1+0.15)*Inputs!B15)*0.7*Inputs!B27*Inputs!B29)*(1-Inputs!B30)))/((Inputs!B7+((Inputs!B16*(1+0.15)*Inputs!B15)*(1-0.7)/Inputs!B8))*100))-(Inputs!B6/(Inputs!B7*100)))/(Inputs!B6/(Inputs!B7*100)) -> -0.080840718 | K7: =(((Inputs!B6+Inputs!B14+(Inputs!B34*Inputs!B35*(1-Inputs!B30))-(((Inputs!B16*(1+0.15)*Inputs!B15)*0.8*Inputs!B26*Inputs!B28+(Inputs!B16*(1+0.15)*Inputs!B15)*0.8*Inputs!B27*Inputs!B29)*(1-Inputs!B30)))/((Inputs!B7+((Inputs!B16*(1+0.15)*Inputs!B15)*(1-0.8)/Inputs!B8))*100))-(Inputs!B6/(Inputs!B7*100)))/(Inputs!B6/(Inputs!B7*100)) -> -0.084375592 | L7: =(((Inputs!B6+Inputs!B14+(Inputs!B34*Inputs!B35*(1-Inputs!B30))-(((Inputs!B16*(1+0.15)*Inputs!B15)*0.9*Inputs!B26*Inputs!B28+(Inputs!B16*(1+0.15)*Inputs!B15)*0.9*Inputs!B27*Inputs!B29)*(1-Inputs!B30)))/((Inputs!B7+((Inputs!B16*(1+0.15)*Inputs!B15)*(1-0.9)/Inputs!B8))*100))-(Inputs!B6/(Inputs!B7*100)))/(Inputs!B6/(Inputs!B7*100)) -> -0.088026141 | M7: =(((Inputs!B6+Inputs!B14+(Inputs!B34*Inputs!B35*(1-Inputs!B30))-(((Inputs!B16*(1+0.15)*Inputs!B15)*1*Inputs!B26*Inputs!B28+(Inputs!B16*(1+0.15)*Inputs!B15)*1*Inputs!B27*Inputs!B29)*(1-Inputs!B30)))/((Inputs!B7+((Inputs!B16*(1+0.15)*Inputs!B15)*(1-1)/Inputs!B8))*100))-(Inputs!B6/(Inputs!B7*100)))/(Inputs!B6/(Inputs!B7*100)) -> -0.09179814
B8: 0.2 | C8: =(((Inputs!B6+Inputs!B14+(Inputs!B34*Inputs!B35*(1-Inputs!B30))-(((Inputs!B16*(1+0.2)*Inputs!B15)*0*Inputs!B26*Inputs!B28+(Inputs!B16*(1+0.2)*Inputs!B15)*0*Inputs!B27*Inputs!B29)*(1-Inputs!B30)))/((Inputs!B7+((Inputs!B16*(1+0.2)*Inputs!B15)*(1-0)/Inputs!B8))*100))-(Inputs!B6/(Inputs!B7*100)))/(Inputs!B6/(Inputs!B7*100)) -> -0.064719318 | D8: =(((Inputs!B6+Inputs!B14+(Inputs!B34*Inputs!B35*(1-Inputs!B30))-(((Inputs!B16*(1+0.2)*Inputs!B15)*0.1*Inputs!B26*Inputs!B28+(Inputs!B16*(1+0.2)*Inputs!B15)*0.1*Inputs!B27*Inputs!B29)*(1-Inputs!B30)))/((Inputs!B7+((Inputs!B16*(1+0.2)*Inputs!B15)*(1-0.1)/Inputs!B8))*100))-(Inputs!B6/(Inputs!B7*100)))/(Inputs!B6/(Inputs!B7*100)) -> -0.067773629 | E8: =(((Inputs!B6+Inputs!B14+(Inputs!B34*Inputs!B35*(1-Inputs!B30))-(((Inputs!B16*(1+0.2)*Inputs!B15)*0.2*Inputs!B26*Inputs!B28+(Inputs!B16*(1+0.2)*Inputs!B15)*0.2*Inputs!B27*Inputs!B29)*(1-Inputs!B30)))/((Inputs!B7+((Inputs!B16*(1+0.2)*Inputs!B15)*(1-0.2)/Inputs!B8))*100))-(Inputs!B6/(Inputs!B7*100)))/(Inputs!B6/(Inputs!B7*100)) -> -0.070921043 | F8: =(((Inputs!B6+Inputs!B14+(Inputs!B34*Inputs!B35*(1-Inputs!B30))-(((Inputs!B16*(1+0.2)*Inputs!B15)*0.3*Inputs!B26*Inputs!B28+(Inputs!B16*(1+0.2)*Inputs!B15)*0.3*Inputs!B27*Inputs!B29)*(1-Inputs!B30)))/((Inputs!B7+((Inputs!B16*(1+0.2)*Inputs!B15)*(1-0.3)/Inputs!B8))*100))-(Inputs!B6/(Inputs!B7*100)))/(Inputs!B6/(Inputs!B7*100)) -> -0.074165882 | G8: =(((Inputs!B6+Inputs!B14+(Inputs!B34*Inputs!B35*(1-Inputs!B30))-(((Inputs!B16*(1+0.2)*Inputs!B15)*0.4*Inputs!B26*Inputs!B28+(Inputs!B16*(1+0.2)*Inputs!B15)*0.4*Inputs!B27*Inputs!B29)*(1-Inputs!B30)))/((Inputs!B7+((Inputs!B16*(1+0.2)*Inputs!B15)*(1-0.4)/Inputs!B8))*100))-(Inputs!B6/(Inputs!B7*100)))/(Inputs!B6/(Inputs!B7*100)) -> -0.077512742 | H8: =(((Inputs!B6+Inputs!B14+(Inputs!B34*Inputs!B35*(1-Inputs!B30))-(((Inputs!B16*(1+0.2)*Inputs!B15)*0.5*Inputs!B26*Inputs!B28+(Inputs!B16*(1+0.2)*Inputs!B15)*0.5*Inputs!B27*Inputs!B29)*(1-Inputs!B30)))/((Inputs!B7+((Inputs!B16*(1+0.2)*Inputs!B15)*(1-0.5)/Inputs!B8))*100))-(Inputs!B6/(Inputs!B7*100)))/(Inputs!B6/(Inputs!B7*100)) -> -0.080966509 | I8: =(((Inputs!B6+Inputs!B14+(Inputs!B34*Inputs!B35*(1-Inputs!B30))-(((Inputs!B16*(1+0.2)*Inputs!B15)*0.6*Inputs!B26*Inputs!B28+(Inputs!B16*(1+0.2)*Inputs!B15)*0.6*Inputs!B27*Inputs!B29)*(1-Inputs!B30)))/((Inputs!B7+((Inputs!B16*(1+0.2)*Inputs!B15)*(1-0.6)/Inputs!B8))*100))-(Inputs!B6/(Inputs!B7*100)))/(Inputs!B6/(Inputs!B7*100)) -> -0.08453239 | J8: =(((Inputs!B6+Inputs!B14+(Inputs!B34*Inputs!B35*(1-Inputs!B30))-(((Inputs!B16*(1+0.2)*Inputs!B15)*0.7*Inputs!B26*Inputs!B28+(Inputs!B16*(1+0.2)*Inputs!B15)*0.7*Inputs!B27*Inputs!B29)*(1-Inputs!B30)))/((Inputs!B7+((Inputs!B16*(1+0.2)*Inputs!B15)*(1-0.7)/Inputs!B8))*100))-(Inputs!B6/(Inputs!B7*100)))/(Inputs!B6/(Inputs!B7*100)) -> -0.088215934 | K8: =(((Inputs!B6+Inputs!B14+(Inputs!B34*Inputs!B35*(1-Inputs!B30))-(((Inputs!B16*(1+0.2)*Inputs!B15)*0.8*Inputs!B26*Inputs!B28+(Inputs!B16*(1+0.2)*Inputs!B15)*0.8*Inputs!B27*Inputs!B29)*(1-Inputs!B30)))/((Inputs!B7+((Inputs!B16*(1+0.2)*Inputs!B15)*(1-0.8)/Inputs!B8))*100))-(Inputs!B6/(Inputs!B7*100)))/(Inputs!B6/(Inputs!B7*100)) -> -0.092023061 | L8: =(((Inputs!B6+Inputs!B14+(Inputs!B34*Inputs!B35*(1-Inputs!B30))-(((Inputs!B16*(1+0.2)*Inputs!B15)*0.9*Inputs!B26*Inputs!B28+(Inputs!B16*(1+0.2)*Inputs!B15)*0.9*Inputs!B27*Inputs!B29)*(1-Inputs!B30)))/((Inputs!B7+((Inputs!B16*(1+0.2)*Inputs!B15)*(1-0.9)/Inputs!B8))*100))-(Inputs!B6/(Inputs!B7*100)))/(Inputs!B6/(Inputs!B7*100)) -> -0.095960099 | M8: =(((Inputs!B6+Inputs!B14+(Inputs!B34*Inputs!B35*(1-Inputs!B30))-(((Inputs!B16*(1+0.2)*Inputs!B15)*1*Inputs!B26*Inputs!B28+(Inputs!B16*(1+0.2)*Inputs!B15)*1*Inputs!B27*Inputs!B29)*(1-Inputs!B30)))/((Inputs!B7+((Inputs!B16*(1+0.2)*Inputs!B15)*(1-1)/Inputs!B8))*100))-(Inputs!B6/(Inputs!B7*100)))/(Inputs!B6/(Inputs!B7*100)) -> -0.10003381
B9: 0.25 | C9: =(((Inputs!B6+Inputs!B14+(Inputs!B34*Inputs!B35*(1-Inputs!B30))-(((Inputs!B16*(1+0.25)*Inputs!B15)*0*Inputs!B26*Inputs!B28+(Inputs!B16*(1+0.25)*Inputs!B15)*0*Inputs!B27*Inputs!B29)*(1-Inputs!B30)))/((Inputs!B7+((Inputs!B16*(1+0.25)*Inputs!B15)*(1-0)/Inputs!B8))*100))-(Inputs!B6/(Inputs!B7*100)))/(Inputs!B6/(Inputs!B7*100)) -> -0.070447799 | D9: =(((Inputs!B6+Inputs!B14+(Inputs!B34*Inputs!B35*(1-Inputs!B30))-(((Inputs!B16*(1+0.25)*Inputs!B15)*0.1*Inputs!B26*Inputs!B28+(Inputs!B16*(1+0.25)*Inputs!B15)*0.1*Inputs!B27*Inputs!B29)*(1-Inputs!B30)))/((Inputs!B7+((Inputs!B16*(1+0.25)*Inputs!B15)*(1-0.1)/Inputs!B8))*100))-(Inputs!B6/(Inputs!B7*100)))/(Inputs!B6/(Inputs!B7*100)) -> -0.073700642 | E9: =(((Inputs!B6+Inputs!B14+(Inputs!B34*Inputs!B35*(1-Inputs!B30))-(((Inputs!B16*(1+0.25)*Inputs!B15)*0.2*Inputs!B26*Inputs!B28+(Inputs!B16*(1+0.25)*Inputs!B15)*0.2*Inputs!B27*Inputs!B29)*(1-Inputs!B30)))/((Inputs!B7+((Inputs!B16*(1+0.25)*Inputs!B15)*(1-0.2)/Inputs!B8))*100))-(Inputs!B6/(Inputs!B7*100)))/(Inputs!B6/(Inputs!B7*100)) -> -0.077056249 | F9: =(((Inputs!B6+Inputs!B14+(Inputs!B34*Inputs!B35*(1-Inputs!B30))-(((Inputs!B16*(1+0.25)*Inputs!B15)*0.3*Inputs!B26*Inputs!B28+(Inputs!B16*(1+0.25)*Inputs!B15)*0.3*Inputs!B27*Inputs!B29)*(1-Inputs!B30)))/((Inputs!B7+((Inputs!B16*(1+0.25)*Inputs!B15)*(1-0.3)/Inputs!B8))*100))-(Inputs!B6/(Inputs!B7*100)))/(Inputs!B6/(Inputs!B7*100)) -> -0.080519567 | G9: =(((Inputs!B6+Inputs!B14+(Inputs!B34*Inputs!B35*(1-Inputs!B30))-(((Inputs!B16*(1+0.25)*Inputs!B15)*0.4*Inputs!B26*Inputs!B28+(Inputs!B16*(1+0.25)*Inputs!B15)*0.4*Inputs!B27*Inputs!B29)*(1-Inputs!B30)))/((Inputs!B7+((Inputs!B16*(1+0.25)*Inputs!B15)*(1-0.4)/Inputs!B8))*100))-(Inputs!B6/(Inputs!B7*100)))/(Inputs!B6/(Inputs!B7*100)) -> -0.084095868 | H9: =(((Inputs!B6+Inputs!B14+(Inputs!B34*Inputs!B35*(1-Inputs!B30))-(((Inputs!B16*(1+0.25)*Inputs!B15)*0.5*Inputs!B26*Inputs!B28+(Inputs!B16*(1+0.25)*Inputs!B15)*0.5*Inputs!B27*Inputs!B29)*(1-Inputs!B30)))/((Inputs!B7+((Inputs!B16*(1+0.25)*Inputs!B15)*(1-0.5)/Inputs!B8))*100))-(Inputs!B6/(Inputs!B7*100)))/(Inputs!B6/(Inputs!B7*100)) -> -0.08779077 | I9: =(((Inputs!B6+Inputs!B14+(Inputs!B34*Inputs!B35*(1-Inputs!B30))-(((Inputs!B16*(1+0.25)*Inputs!B15)*0.6*Inputs!B26*Inputs!B28+(Inputs!B16*(1+0.25)*Inputs!B15)*0.6*Inputs!B27*Inputs!B29)*(1-Inputs!B30)))/((Inputs!B7+((Inputs!B16*(1+0.25)*Inputs!B15)*(1-0.6)/Inputs!B8))*100))-(Inputs!B6/(Inputs!B7*100)))/(Inputs!B6/(Inputs!B7*100)) -> -0.091610275 | J9: =(((Inputs!B6+Inputs!B14+(Inputs!B34*Inputs!B35*(1-Inputs!B30))-(((Inputs!B16*(1+0.25)*Inputs!B15)*0.7*Inputs!B26*Inputs!B28+(Inputs!B16*(1+0.25)*Inputs!B15)*0.7*Inputs!B27*Inputs!B29)*(1-Inputs!B30)))/((Inputs!B7+((Inputs!B16*(1+0.25)*Inputs!B15)*(1-0.7)/Inputs!B8))*100))-(Inputs!B6/(Inputs!B7*100)))/(Inputs!B6/(Inputs!B7*100)) -> -0.095560792 | K9: =(((Inputs!B6+Inputs!B14+(Inputs!B34*Inputs!B35*(1-Inputs!B30))-(((Inputs!B16*(1+0.25)*Inputs!B15)*0.8*Inputs!B26*Inputs!B28+(Inputs!B16*(1+0.25)*Inputs!B15)*0.8*Inputs!B27*Inputs!B29)*(1-Inputs!B30)))/((Inputs!B7+((Inputs!B16*(1+0.25)*Inputs!B15)*(1-0.8)/Inputs!B8))*100))-(Inputs!B6/(Inputs!B7*100)))/(Inputs!B6/(Inputs!B7*100)) -> -0.09964918 | L9: =(((Inputs!B6+Inputs!B14+(Inputs!B34*Inputs!B35*(1-Inputs!B30))-(((Inputs!B16*(1+0.25)*Inputs!B15)*0.9*Inputs!B26*Inputs!B28+(Inputs!B16*(1+0.25)*Inputs!B15)*0.9*Inputs!B27*Inputs!B29)*(1-Inputs!B30)))/((Inputs!B7+((Inputs!B16*(1+0.25)*Inputs!B15)*(1-0.9)/Inputs!B8))*100))-(Inputs!B6/(Inputs!B7*100)))/(Inputs!B6/(Inputs!B7*100)) -> -0.10388278 | M9: =(((Inputs!B6+Inputs!B14+(Inputs!B34*Inputs!B35*(1-Inputs!B30))-(((Inputs!B16*(1+0.25)*Inputs!B15)*1*Inputs!B26*Inputs!B28+(Inputs!B16*(1+0.25)*Inputs!B15)*1*Inputs!B27*Inputs!B29)*(1-Inputs!B30)))/((Inputs!B7+((Inputs!B16*(1+0.25)*Inputs!B15)*(1-1)/Inputs!B8))*100))-(Inputs!B6/(Inputs!B7*100)))/(Inputs!B6/(Inputs!B7*100)) -> -0.10826948
B10: 0.3 | C10: =(((Inputs!B6+Inputs!B14+(Inputs!B34*Inputs!B35*(1-Inputs!B30))-(((Inputs!B16*(1+0.3)*Inputs!B15)*0*Inputs!B26*Inputs!B28+(Inputs!B16*(1+0.3)*Inputs!B15)*0*Inputs!B27*Inputs!B29)*(1-Inputs!B30)))/((Inputs!B7+((Inputs!B16*(1+0.3)*Inputs!B15)*(1-0)/Inputs!B8))*100))-(Inputs!B6/(Inputs!B7*100)))/(Inputs!B6/(Inputs!B7*100)) -> -0.076106535 | D10: =(((Inputs!B6+Inputs!B14+(Inputs!B34*Inputs!B35*(1-Inputs!B30))-(((Inputs!B16*(1+0.3)*Inputs!B15)*0.1*Inputs!B26*Inputs!B28+(Inputs!B16*(1+0.3)*Inputs!B15)*0.1*Inputs!B27*Inputs!B29)*(1-Inputs!B30)))/((Inputs!B7+((Inputs!B16*(1+0.3)*Inputs!B15)*(1-0.1)/Inputs!B8))*100))-(Inputs!B6/(Inputs!B7*100)))/(Inputs!B6/(Inputs!B7*100)) -> -0.079561665 | E10: =(((Inputs!B6+Inputs!B14+(Inputs!B34*Inputs!B35*(1-Inputs!B30))-(((Inputs!B16*(1+0.3)*Inputs!B15)*0.2*Inputs!B26*Inputs!B28+(Inputs!B16*(1+0.3)*Inputs!B15)*0.2*Inputs!B27*Inputs!B29)*(1-Inputs!B30)))/((Inputs!B7+((Inputs!B16*(1+0.3)*Inputs!B15)*(1-0.2)/Inputs!B8))*100))-(Inputs!B6/(Inputs!B7*100)))/(Inputs!B6/(Inputs!B7*100)) -> -0.083129744 | F10: =(((Inputs!B6+Inputs!B14+(Inputs!B34*Inputs!B35*(1-Inputs!B30))-(((Inputs!B16*(1+0.3)*Inputs!B15)*0.3*Inputs!B26*Inputs!B28+(Inputs!B16*(1+0.3)*Inputs!B15)*0.3*Inputs!B27*Inputs!B29)*(1-Inputs!B30)))/((Inputs!B7+((Inputs!B16*(1+0.3)*Inputs!B15)*(1-0.3)/Inputs!B8))*100))-(Inputs!B6/(Inputs!B7*100)))/(Inputs!B6/(Inputs!B7*100)) -> -0.086816403 | G10: =(((Inputs!B6+Inputs!B14+(Inputs!B34*Inputs!B35*(1-Inputs!B30))-(((Inputs!B16*(1+0.3)*Inputs!B15)*0.4*Inputs!B26*Inputs!B28+(Inputs!B16*(1+0.3)*Inputs!B15)*0.4*Inputs!B27*Inputs!B29)*(1-Inputs!B30)))/((Inputs!B7+((Inputs!B16*(1+0.3)*Inputs!B15)*(1-0.4)/Inputs!B8))*100))-(Inputs!B6/(Inputs!B7*100)))/(Inputs!B6/(Inputs!B7*100)) -> -0.090627653 | H10: =(((Inputs!B6+Inputs!B14+(Inputs!B34*Inputs!B35*(1-Inputs!B30))-(((Inputs!B16*(1+0.3)*Inputs!B15)*0.5*Inputs!B26*Inputs!B28+(Inputs!B16*(1+0.3)*Inputs!B15)*0.5*Inputs!B27*Inputs!B29)*(1-Inputs!B30)))/((Inputs!B7+((Inputs!B16*(1+0.3)*Inputs!B15)*(1-0.5)/Inputs!B8))*100))-(Inputs!B6/(Inputs!B7*100)))/(Inputs!B6/(Inputs!B7*100)) -> -0.094569918 | I10: =(((Inputs!B6+Inputs!B14+(Inputs!B34*Inputs!B35*(1-Inputs!B30))-(((Inputs!B16*(1+0.3)*Inputs!B15)*0.6*Inputs!B26*Inputs!B28+(Inputs!B16*(1+0.3)*Inputs!B15)*0.6*Inputs!B27*Inputs!B29)*(1-Inputs!B30)))/((Inputs!B7+((Inputs!B16*(1+0.3)*Inputs!B15)*(1-0.6)/Inputs!B8))*100))-(Inputs!B6/(Inputs!B7*100)))/(Inputs!B6/(Inputs!B7*100)) -> -0.098650073 | J10: =(((Inputs!B6+Inputs!B14+(Inputs!B34*Inputs!B35*(1-Inputs!B30))-(((Inputs!B16*(1+0.3)*Inputs!B15)*0.7*Inputs!B26*Inputs!B28+(Inputs!B16*(1+0.3)*Inputs!B15)*0.7*Inputs!B27*Inputs!B29)*(1-Inputs!B30)))/((Inputs!B7+((Inputs!B16*(1+0.3)*Inputs!B15)*(1-0.7)/Inputs!B8))*100))-(Inputs!B6/(Inputs!B7*100)))/(Inputs!B6/(Inputs!B7*100)) -> -0.10287548 | K10: =(((Inputs!B6+Inputs!B14+(Inputs!B34*Inputs!B35*(1-Inputs!B30))-(((Inputs!B16*(1+0.3)*Inputs!B15)*0.8*Inputs!B26*Inputs!B28+(Inputs!B16*(1+0.3)*Inputs!B15)*0.8*Inputs!B27*Inputs!B29)*(1-Inputs!B30)))/((Inputs!B7+((Inputs!B16*(1+0.3)*Inputs!B15)*(1-0.8)/Inputs!B8))*100))-(Inputs!B6/(Inputs!B7*100)))/(Inputs!B6/(Inputs!B7*100)) -> -0.10725404 | L10: =(((Inputs!B6+Inputs!B14+(Inputs!B34*Inputs!B35*(1-Inputs!B30))-(((Inputs!B16*(1+0.3)*Inputs!B15)*0.9*Inputs!B26*Inputs!B28+(Inputs!B16*(1+0.3)*Inputs!B15)*0.9*Inputs!B27*Inputs!B29)*(1-Inputs!B30)))/((Inputs!B7+((Inputs!B16*(1+0.3)*Inputs!B15)*(1-0.9)/Inputs!B8))*100))-(Inputs!B6/(Inputs!B7*100)))/(Inputs!B6/(Inputs!B7*100)) -> -0.11179422 | M10: =(((Inputs!B6+Inputs!B14+(Inputs!B34*Inputs!B35*(1-Inputs!B30))-(((Inputs!B16*(1+0.3)*Inputs!B15)*1*Inputs!B26*Inputs!B28+(Inputs!B16*(1+0.3)*Inputs!B15)*1*Inputs!B27*Inputs!B29)*(1-Inputs!B30)))/((Inputs!B7+((Inputs!B16*(1+0.3)*Inputs!B15)*(1-1)/Inputs!B8))*100))-(Inputs!B6/(Inputs!B7*100)))/(Inputs!B6/(Inputs!B7*100)) -> -0.11650515
B11: 0.35 | C11: =(((Inputs!B6+Inputs!B14+(Inputs!B34*Inputs!B35*(1-Inputs!B30))-(((Inputs!B16*(1+0.35)*Inputs!B15)*0*Inputs!B26*Inputs!B28+(Inputs!B16*(1+0.35)*Inputs!B15)*0*Inputs!B27*Inputs!B29)*(1-Inputs!B30)))/((Inputs!B7+((Inputs!B16*(1+0.35)*Inputs!B15)*(1-0)/Inputs!B8))*100))-(Inputs!B6/(Inputs!B7*100)))/(Inputs!B6/(Inputs!B7*100)) -> -0.081696791 | D11: =(((Inputs!B6+Inputs!B14+(Inputs!B34*Inputs!B35*(1-Inputs!B30))-(((Inputs!B16*(1+0.35)*Inputs!B15)*0.1*Inputs!B26*Inputs!B28+(Inputs!B16*(1+0.35)*Inputs!B15)*0.1*Inputs!B27*Inputs!B29)*(1-Inputs!B30)))/((Inputs!B7+((Inputs!B16*(1+0.35)*Inputs!B15)*(1-0.1)/Inputs!B8))*100))-(Inputs!B6/(Inputs!B7*100)))/(Inputs!B6/(Inputs!B7*100)) -> -0.085357792 | E11: =(((Inputs!B6+Inputs!B14+(Inputs!B34*Inputs!B35*(1-Inputs!B30))-(((Inputs!B16*(1+0.35)*Inputs!B15)*0.2*Inputs!B26*Inputs!B28+(Inputs!B16*(1+0.35)*Inputs!B15)*0.2*Inputs!B27*Inputs!B29)*(1-Inputs!B30)))/((Inputs!B7+((Inputs!B16*(1+0.35)*Inputs!B15)*(1-0.2)/Inputs!B8))*100))-(Inputs!B6/(Inputs!B7*100)))/(Inputs!B6/(Inputs!B7*100)) -> -0.089142454 | F11: =(((Inputs!B6+Inputs!B14+(Inputs!B34*Inputs!B35*(1-Inputs!B30))-(((Inputs!B16*(1+0.35)*Inputs!B15)*0.3*Inputs!B26*Inputs!B28+(Inputs!B16*(1+0.35)*Inputs!B15)*0.3*Inputs!B27*Inputs!B29)*(1-Inputs!B30)))/((Inputs!B7+((Inputs!B16*(1+0.35)*Inputs!B15)*(1-0.3)/Inputs!B8))*100))-(Inputs!B6/(Inputs!B7*100)))/(Inputs!B6/(Inputs!B7*100)) -> -0.093057148 | G11: =(((Inputs!B6+Inputs!B14+(Inputs!B34*Inputs!B35*(1-Inputs!B30))-(((Inputs!B16*(1+0.35)*Inputs!B15)*0.4*Inputs!B26*Inputs!B28+(Inputs!B16*(1+0.35)*Inputs!B15)*0.4*Inputs!B27*Inputs!B29)*(1-Inputs!B30)))/((Inputs!B7+((Inputs!B16*(1+0.35)*Inputs!B15)*(1-0.4)/Inputs!B8))*100))-(Inputs!B6/(Inputs!B7*100)))/(Inputs!B6/(Inputs!B7*100)) -> -0.097108695 | H11: =(((Inputs!B6+Inputs!B14+(Inputs!B34*Inputs!B35*(1-Inputs!B30))-(((Inputs!B16*(1+0.35)*Inputs!B15)*0.5*Inputs!B26*Inputs!B28+(Inputs!B16*(1+0.35)*Inputs!B15)*0.5*Inputs!B27*Inputs!B29)*(1-Inputs!B30)))/((Inputs!B7+((Inputs!B16*(1+0.35)*Inputs!B15)*(1-0.5)/Inputs!B8))*100))-(Inputs!B6/(Inputs!B7*100)))/(Inputs!B6/(Inputs!B7*100)) -> -0.1013044 | I11: =(((Inputs!B6+Inputs!B14+(Inputs!B34*Inputs!B35*(1-Inputs!B30))-(((Inputs!B16*(1+0.35)*Inputs!B15)*0.6*Inputs!B26*Inputs!B28+(Inputs!B16*(1+0.35)*Inputs!B15)*0.6*Inputs!B27*Inputs!B29)*(1-Inputs!B30)))/((Inputs!B7+((Inputs!B16*(1+0.35)*Inputs!B15)*(1-0.6)/Inputs!B8))*100))-(Inputs!B6/(Inputs!B7*100)))/(Inputs!B6/(Inputs!B7*100)) -> -0.10565209 | J11: =(((Inputs!B6+Inputs!B14+(Inputs!B34*Inputs!B35*(1-Inputs!B30))-(((Inputs!B16*(1+0.35)*Inputs!B15)*0.7*Inputs!B26*Inputs!B28+(Inputs!B16*(1+0.35)*Inputs!B15)*0.7*Inputs!B27*Inputs!B29)*(1-Inputs!B30)))/((Inputs!B7+((Inputs!B16*(1+0.35)*Inputs!B15)*(1-0.7)/Inputs!B8))*100))-(Inputs!B6/(Inputs!B7*100)))/(Inputs!B6/(Inputs!B7*100)) -> -0.11016018 | K11: =(((Inputs!B6+Inputs!B14+(Inputs!B34*Inputs!B35*(1-Inputs!B30))-(((Inputs!B16*(1+0.35)*Inputs!B15)*0.8*Inputs!B26*Inputs!B28+(Inputs!B16*(1+0.35)*Inputs!B15)*0.8*Inputs!B27*Inputs!B29)*(1-Inputs!B30)))/((Inputs!B7+((Inputs!B16*(1+0.35)*Inputs!B15)*(1-0.8)/Inputs!B8))*100))-(Inputs!B6/(Inputs!B7*100)))/(Inputs!B6/(Inputs!B7*100)) -> -0.11483772 | L11: =(((Inputs!B6+Inputs!B14+(Inputs!B34*Inputs!B35*(1-Inputs!B30))-(((Inputs!B16*(1+0.35)*Inputs!B15)*0.9*Inputs!B26*Inputs!B28+(Inputs!B16*(1+0.35)*Inputs!B15)*0.9*Inputs!B27*Inputs!B29)*(1-Inputs!B30)))/((Inputs!B7+((Inputs!B16*(1+0.35)*Inputs!B15)*(1-0.9)/Inputs!B8))*100))-(Inputs!B6/(Inputs!B7*100)))/(Inputs!B6/(Inputs!B7*100)) -> -0.11969443 | M11: =(((Inputs!B6+Inputs!B14+(Inputs!B34*Inputs!B35*(1-Inputs!B30))-(((Inputs!B16*(1+0.35)*Inputs!B15)*1*Inputs!B26*Inputs!B28+(Inputs!B16*(1+0.35)*Inputs!B15)*1*Inputs!B27*Inputs!B29)*(1-Inputs!B30)))/((Inputs!B7+((Inputs!B16*(1+0.35)*Inputs!B15)*(1-1)/Inputs!B8))*100))-(Inputs!B6/(Inputs!B7*100)))/(Inputs!B6/(Inputs!B7*100)) -> -0.12474083
B12: 0.4 | C12: =(((Inputs!B6+Inputs!B14+(Inputs!B34*Inputs!B35*(1-Inputs!B30))-(((Inputs!B16*(1+0.4)*Inputs!B15)*0*Inputs!B26*Inputs!B28+(Inputs!B16*(1+0.4)*Inputs!B15)*0*Inputs!B27*Inputs!B29)*(1-Inputs!B30)))/((Inputs!B7+((Inputs!B16*(1+0.4)*Inputs!B15)*(1-0)/Inputs!B8))*100))-(Inputs!B6/(Inputs!B7*100)))/(Inputs!B6/(Inputs!B7*100)) -> -0.087219804 | D12: =(((Inputs!B6+Inputs!B14+(Inputs!B34*Inputs!B35*(1-Inputs!B30))-(((Inputs!B16*(1+0.4)*Inputs!B15)*0.1*Inputs!B26*Inputs!B28+(Inputs!B16*(1+0.4)*Inputs!B15)*0.1*Inputs!B27*Inputs!B29)*(1-Inputs!B30)))/((Inputs!B7+((Inputs!B16*(1+0.4)*Inputs!B15)*(1-0.1)/Inputs!B8))*100))-(Inputs!B6/(Inputs!B7*100)))/(Inputs!B6/(Inputs!B7*100)) -> -0.091090097 | E12: =(((Inputs!B6+Inputs!B14+(Inputs!B34*Inputs!B35*(1-Inputs!B30))-(((Inputs!B16*(1+0.4)*Inputs!B15)*0.2*Inputs!B26*Inputs!B28+(Inputs!B16*(1+0.4)*Inputs!B15)*0.2*Inputs!B27*Inputs!B29)*(1-Inputs!B30)))/((Inputs!B7+((Inputs!B16*(1+0.4)*Inputs!B15)*(1-0.2)/Inputs!B8))*100))-(Inputs!B6/(Inputs!B7*100)))/(Inputs!B6/(Inputs!B7*100)) -> -0.095095286 | F12: =(((Inputs!B6+Inputs!B14+(Inputs!B34*Inputs!B35*(1-Inputs!B30))-(((Inputs!B16*(1+0.4)*Inputs!B15)*0.3*Inputs!B26*Inputs!B28+(Inputs!B16*(1+0.4)*Inputs!B15)*0.3*Inputs!B27*Inputs!B29)*(1-Inputs!B30)))/((Inputs!B7+((Inputs!B16*(1+0.4)*Inputs!B15)*(1-0.3)/Inputs!B8))*100))-(Inputs!B6/(Inputs!B7*100)))/(Inputs!B6/(Inputs!B7*100)) -> -0.09924255 | G12: =(((Inputs!B6+Inputs!B14+(Inputs!B34*Inputs!B35*(1-Inputs!B30))-(((Inputs!B16*(1+0.4)*Inputs!B15)*0.4*Inputs!B26*Inputs!B28+(Inputs!B16*(1+0.4)*Inputs!B15)*0.4*Inputs!B27*Inputs!B29)*(1-Inputs!B30)))/((Inputs!B7+((Inputs!B16*(1+0.4)*Inputs!B15)*(1-0.4)/Inputs!B8))*100))-(Inputs!B6/(Inputs!B7*100)))/(Inputs!B6/(Inputs!B7*100)) -> -0.10353958 | H12: =(((Inputs!B6+Inputs!B14+(Inputs!B34*Inputs!B35*(1-Inputs!B30))-(((Inputs!B16*(1+0.4)*Inputs!B15)*0.5*Inputs!B26*Inputs!B28+(Inputs!B16*(1+0.4)*Inputs!B15)*0.5*Inputs!B27*Inputs!B29)*(1-Inputs!B30)))/((Inputs!B7+((Inputs!B16*(1+0.4)*Inputs!B15)*(1-0.5)/Inputs!B8))*100))-(Inputs!B6/(Inputs!B7*100)))/(Inputs!B6/(Inputs!B7*100)) -> -0.10799465 | I12: =(((Inputs!B6+Inputs!B14+(Inputs!B34*Inputs!B35*(1-Inputs!B30))-(((Inputs!B16*(1+0.4)*Inputs!B15)*0.6*Inputs!B26*Inputs!B28+(Inputs!B16*(1+0.4)*Inputs!B15)*0.6*Inputs!B27*Inputs!B29)*(1-Inputs!B30)))/((Inputs!B7+((Inputs!B16*(1+0.4)*Inputs!B15)*(1-0.6)/Inputs!B8))*100))-(Inputs!B6/(Inputs!B7*100)))/(Inputs!B6/(Inputs!B7*100)) -> -0.11261663 | J12: =(((Inputs!B6+Inputs!B14+(Inputs!B34*Inputs!B35*(1-Inputs!B30))-(((Inputs!B16*(1+0.4)*Inputs!B15)*0.7*Inputs!B26*Inputs!B28+(Inputs!B16*(1+0.4)*Inputs!B15)*0.7*Inputs!B27*Inputs!B29)*(1-Inputs!B30)))/((Inputs!B7+((Inputs!B16*(1+0.4)*Inputs!B15)*(1-0.7)/Inputs!B8))*100))-(Inputs!B6/(Inputs!B7*100)))/(Inputs!B6/(Inputs!B7*100)) -> -0.11741509 | K12: =(((Inputs!B6+Inputs!B14+(Inputs!B34*Inputs!B35*(1-Inputs!B30))-(((Inputs!B16*(1+0.4)*Inputs!B15)*0.8*Inputs!B26*Inputs!B28+(Inputs!B16*(1+0.4)*Inputs!B15)*0.8*Inputs!B27*Inputs!B29)*(1-Inputs!B30)))/((Inputs!B7+((Inputs!B16*(1+0.4)*Inputs!B15)*(1-0.8)/Inputs!B8))*100))-(Inputs!B6/(Inputs!B7*100)))/(Inputs!B6/(Inputs!B7*100)) -> -0.12240032 | L12: =(((Inputs!B6+Inputs!B14+(Inputs!B34*Inputs!B35*(1-Inputs!B30))-(((Inputs!B16*(1+0.4)*Inputs!B15)*0.9*Inputs!B26*Inputs!B28+(Inputs!B16*(1+0.4)*Inputs!B15)*0.9*Inputs!B27*Inputs!B29)*(1-Inputs!B30)))/((Inputs!B7+((Inputs!B16*(1+0.4)*Inputs!B15)*(1-0.9)/Inputs!B8))*100))-(Inputs!B6/(Inputs!B7*100)))/(Inputs!B6/(Inputs!B7*100)) -> -0.12758345 | M12: =(((Inputs!B6+Inputs!B14+(Inputs!B34*Inputs!B35*(1-Inputs!B30))-(((Inputs!B16*(1+0.4)*Inputs!B15)*1*Inputs!B26*Inputs!B28+(Inputs!B16*(1+0.4)*Inputs!B15)*1*Inputs!B27*Inputs!B29)*(1-Inputs!B30)))/((Inputs!B7+((Inputs!B16*(1+0.4)*Inputs!B15)*(1-1)/Inputs!B8))*100))-(Inputs!B6/(Inputs!B7*100)))/(Inputs!B6/(Inputs!B7*100)) -> -0.1329765
B13: 0.45 | C13: =(((Inputs!B6+Inputs!B14+(Inputs!B34*Inputs!B35*(1-Inputs!B30))-(((Inputs!B16*(1+0.45)*Inputs!B15)*0*Inputs!B26*Inputs!B28+(Inputs!B16*(1+0.45)*Inputs!B15)*0*Inputs!B27*Inputs!B29)*(1-Inputs!B30)))/((Inputs!B7+((Inputs!B16*(1+0.45)*Inputs!B15)*(1-0)/Inputs!B8))*100))-(Inputs!B6/(Inputs!B7*100)))/(Inputs!B6/(Inputs!B7*100)) -> -0.09267678 | D13: =(((Inputs!B6+Inputs!B14+(Inputs!B34*Inputs!B35*(1-Inputs!B30))-(((Inputs!B16*(1+0.45)*Inputs!B15)*0.1*Inputs!B26*Inputs!B28+(Inputs!B16*(1+0.45)*Inputs!B15)*0.1*Inputs!B27*Inputs!B29)*(1-Inputs!B30)))/((Inputs!B7+((Inputs!B16*(1+0.45)*Inputs!B15)*(1-0.1)/Inputs!B8))*100))-(Inputs!B6/(Inputs!B7*100)))/(Inputs!B6/(Inputs!B7*100)) -> -0.096759627 | E13: =(((Inputs!B6+Inputs!B14+(Inputs!B34*Inputs!B35*(1-Inputs!B30))-(((Inputs!B16*(1+0.45)*Inputs!B15)*0.2*Inputs!B26*Inputs!B28+(Inputs!B16*(1+0.45)*Inputs!B15)*0.2*Inputs!B27*Inputs!B29)*(1-Inputs!B30)))/((Inputs!B7+((Inputs!B16*(1+0.45)*Inputs!B15)*(1-0.2)/Inputs!B8))*100))-(Inputs!B6/(Inputs!B7*100)))/(Inputs!B6/(Inputs!B7*100)) -> -0.10098913 | F13: =(((Inputs!B6+Inputs!B14+(Inputs!B34*Inputs!B35*(1-Inputs!B30))-(((Inputs!B16*(1+0.45)*Inputs!B15)*0.3*Inputs!B26*Inputs!B28+(Inputs!B16*(1+0.45)*Inputs!B15)*0.3*Inputs!B27*Inputs!B29)*(1-Inputs!B30)))/((Inputs!B7+((Inputs!B16*(1+0.45)*Inputs!B15)*(1-0.3)/Inputs!B8))*100))-(Inputs!B6/(Inputs!B7*100)))/(Inputs!B6/(Inputs!B7*100)) -> -0.10537334 | G13: =(((Inputs!B6+Inputs!B14+(Inputs!B34*Inputs!B35*(1-Inputs!B30))-(((Inputs!B16*(1+0.45)*Inputs!B15)*0.4*Inputs!B26*Inputs!B28+(Inputs!B16*(1+0.45)*Inputs!B15)*0.4*Inputs!B27*Inputs!B29)*(1-Inputs!B30)))/((Inputs!B7+((Inputs!B16*(1+0.45)*Inputs!B15)*(1-0.4)/Inputs!B8))*100))-(Inputs!B6/(Inputs!B7*100)))/(Inputs!B6/(Inputs!B7*100)) -> -0.1099209 | H13: =(((Inputs!B6+Inputs!B14+(Inputs!B34*Inputs!B35*(1-Inputs!B30))-(((Inputs!B16*(1+0.45)*Inputs!B15)*0.5*Inputs!B26*Inputs!B28+(Inputs!B16*(1+0.45)*Inputs!B15)*0.5*Inputs!B27*Inputs!B29)*(1-Inputs!B30)))/((Inputs!B7+((Inputs!B16*(1+0.45)*Inputs!B15)*(1-0.5)/Inputs!B8))*100))-(Inputs!B6/(Inputs!B7*100)))/(Inputs!B6/(Inputs!B7*100)) -> -0.11464111 | I13: =(((Inputs!B6+Inputs!B14+(Inputs!B34*Inputs!B35*(1-Inputs!B30))-(((Inputs!B16*(1+0.45)*Inputs!B15)*0.6*Inputs!B26*Inputs!B28+(Inputs!B16*(1+0.45)*Inputs!B15)*0.6*Inputs!B27*Inputs!B29)*(1-Inputs!B30)))/((Inputs!B7+((Inputs!B16*(1+0.45)*Inputs!B15)*(1-0.6)/Inputs!B8))*100))-(Inputs!B6/(Inputs!B7*100)))/(Inputs!B6/(Inputs!B7*100)) -> -0.119544 | J13: =(((Inputs!B6+Inputs!B14+(Inputs!B34*Inputs!B35*(1-Inputs!B30))-(((Inputs!B16*(1+0.45)*Inputs!B15)*0.7*Inputs!B26*Inputs!B28+(Inputs!B16*(1+0.45)*Inputs!B15)*0.7*Inputs!B27*Inputs!B29)*(1-Inputs!B30)))/((Inputs!B7+((Inputs!B16*(1+0.45)*Inputs!B15)*(1-0.7)/Inputs!B8))*100))-(Inputs!B6/(Inputs!B7*100)))/(Inputs!B6/(Inputs!B7*100)) -> -0.12464037 | K13: =(((Inputs!B6+Inputs!B14+(Inputs!B34*Inputs!B35*(1-Inputs!B30))-(((Inputs!B16*(1+0.45)*Inputs!B15)*0.8*Inputs!B26*Inputs!B28+(Inputs!B16*(1+0.45)*Inputs!B15)*0.8*Inputs!B27*Inputs!B29)*(1-Inputs!B30)))/((Inputs!B7+((Inputs!B16*(1+0.45)*Inputs!B15)*(1-0.8)/Inputs!B8))*100))-(Inputs!B6/(Inputs!B7*100)))/(Inputs!B6/(Inputs!B7*100)) -> -0.12994192 | L13: =(((Inputs!B6+Inputs!B14+(Inputs!B34*Inputs!B35*(1-Inputs!B30))-(((Inputs!B16*(1+0.45)*Inputs!B15)*0.9*Inputs!B26*Inputs!B28+(Inputs!B16*(1+0.45)*Inputs!B15)*0.9*Inputs!B27*Inputs!B29)*(1-Inputs!B30)))/((Inputs!B7+((Inputs!B16*(1+0.45)*Inputs!B15)*(1-0.9)/Inputs!B8))*100))-(Inputs!B6/(Inputs!B7*100)))/(Inputs!B6/(Inputs!B7*100)) -> -0.13546128 | M13: =(((Inputs!B6+Inputs!B14+(Inputs!B34*Inputs!B35*(1-Inputs!B30))-(((Inputs!B16*(1+0.45)*Inputs!B15)*1*Inputs!B26*Inputs!B28+(Inputs!B16*(1+0.45)*Inputs!B15)*1*Inputs!B27*Inputs!B29)*(1-Inputs!B30)))/((Inputs!B7+((Inputs!B16*(1+0.45)*Inputs!B15)*(1-1)/Inputs!B8))*100))-(Inputs!B6/(Inputs!B7*100)))/(Inputs!B6/(Inputs!B7*100)) -> -0.14121217
B15: TABLE 2 — YEAR 3 ACCRETION / (DILUTION) % (synergy ramp 70% of run-rate)
B16: Row input: Offer Premium | Column input: % Cash Consideration | Formula independent — no Excel Data Table engine required
B17: Premium ↓ / Cash % → | C17: 0 | D17: 0.1 | E17: 0.2 | F17: 0.3 | G17: 0.4 | H17: 0.5 | I17: 0.6 | J17: 0.7 | K17: 0.8 | L17: 0.9 | M17: 1
B18: 0.15 | C18: =(((Inputs!B6+Inputs!B14+(Inputs!B34*Inputs!B37*(1-Inputs!B30))-(((Inputs!B16*(1+0.15)*Inputs!B15)*0*Inputs!B26*Inputs!B28+(Inputs!B16*(1+0.15)*Inputs!B15)*0*Inputs!B27*Inputs!B29)*(1-Inputs!B30)))/((Inputs!B7+((Inputs!B16*(1+0.15)*Inputs!B15)*(1-0)/Inputs!B8))*100))-(Inputs!B6/(Inputs!B7*100)))/(Inputs!B6/(Inputs!B7*100)) -> -0.018671485 | D18: =(((Inputs!B6+Inputs!B14+(Inputs!B34*Inputs!B37*(1-Inputs!B30))-(((Inputs!B16*(1+0.15)*Inputs!B15)*0.1*Inputs!B26*Inputs!B28+(Inputs!B16*(1+0.15)*Inputs!B15)*0.1*Inputs!B27*Inputs!B29)*(1-Inputs!B30)))/((Inputs!B7+((Inputs!B16*(1+0.15)*Inputs!B15)*(1-0.1)/Inputs!B8))*100))-(Inputs!B6/(Inputs!B7*100)))/(Inputs!B6/(Inputs!B7*100)) -> -0.020948872 | E18: =(((Inputs!B6+Inputs!B14+(Inputs!B34*Inputs!B37*(1-Inputs!B30))-(((Inputs!B16*(1+0.15)*Inputs!B15)*0.2*Inputs!B26*Inputs!B28+(Inputs!B16*(1+0.15)*Inputs!B15)*0.2*Inputs!B27*Inputs!B29)*(1-Inputs!B30)))/((Inputs!B7+((Inputs!B16*(1+0.15)*Inputs!B15)*(1-0.2)/Inputs!B8))*100))-(Inputs!B6/(Inputs!B7*100)))/(Inputs!B6/(Inputs!B7*100)) -> -0.023293127 | F18: =(((Inputs!B6+Inputs!B14+(Inputs!B34*Inputs!B37*(1-Inputs!B30))-(((Inputs!B16*(1+0.15)*Inputs!B15)*0.3*Inputs!B26*Inputs!B28+(Inputs!B16*(1+0.15)*Inputs!B15)*0.3*Inputs!B27*Inputs!B29)*(1-Inputs!B30)))/((Inputs!B7+((Inputs!B16*(1+0.15)*Inputs!B15)*(1-0.3)/Inputs!B8))*100))-(Inputs!B6/(Inputs!B7*100)))/(Inputs!B6/(Inputs!B7*100)) -> -0.025707238 | G18: =(((Inputs!B6+Inputs!B14+(Inputs!B34*Inputs!B37*(1-Inputs!B30))-(((Inputs!B16*(1+0.15)*Inputs!B15)*0.4*Inputs!B26*Inputs!B28+(Inputs!B16*(1+0.15)*Inputs!B15)*0.4*Inputs!B27*Inputs!B29)*(1-Inputs!B30)))/((Inputs!B7+((Inputs!B16*(1+0.15)*Inputs!B15)*(1-0.4)/Inputs!B8))*100))-(Inputs!B6/(Inputs!B7*100)))/(Inputs!B6/(Inputs!B7*100)) -> -0.028194374 | H18: =(((Inputs!B6+Inputs!B14+(Inputs!B34*Inputs!B37*(1-Inputs!B30))-(((Inputs!B16*(1+0.15)*Inputs!B15)*0.5*Inputs!B26*Inputs!B28+(Inputs!B16*(1+0.15)*Inputs!B15)*0.5*Inputs!B27*Inputs!B29)*(1-Inputs!B30)))/((Inputs!B7+((Inputs!B16*(1+0.15)*Inputs!B15)*(1-0.5)/Inputs!B8))*100))-(Inputs!B6/(Inputs!B7*100)))/(Inputs!B6/(Inputs!B7*100)) -> -0.030757901 | I18: =(((Inputs!B6+Inputs!B14+(Inputs!B34*Inputs!B37*(1-Inputs!B30))-(((Inputs!B16*(1+0.15)*Inputs!B15)*0.6*Inputs!B26*Inputs!B28+(Inputs!B16*(1+0.15)*Inputs!B15)*0.6*Inputs!B27*Inputs!B29)*(1-Inputs!B30)))/((Inputs!B7+((Inputs!B16*(1+0.15)*Inputs!B15)*(1-0.6)/Inputs!B8))*100))-(Inputs!B6/(Inputs!B7*100)))/(Inputs!B6/(Inputs!B7*100)) -> -0.033401392 | J18: =(((Inputs!B6+Inputs!B14+(Inputs!B34*Inputs!B37*(1-Inputs!B30))-(((Inputs!B16*(1+0.15)*Inputs!B15)*0.7*Inputs!B26*Inputs!B28+(Inputs!B16*(1+0.15)*Inputs!B15)*0.7*Inputs!B27*Inputs!B29)*(1-Inputs!B30)))/((Inputs!B7+((Inputs!B16*(1+0.15)*Inputs!B15)*(1-0.7)/Inputs!B8))*100))-(Inputs!B6/(Inputs!B7*100)))/(Inputs!B6/(Inputs!B7*100)) -> -0.036128648 | K18: =(((Inputs!B6+Inputs!B14+(Inputs!B34*Inputs!B37*(1-Inputs!B30))-(((Inputs!B16*(1+0.15)*Inputs!B15)*0.8*Inputs!B26*Inputs!B28+(Inputs!B16*(1+0.15)*Inputs!B15)*0.8*Inputs!B27*Inputs!B29)*(1-Inputs!B30)))/((Inputs!B7+((Inputs!B16*(1+0.15)*Inputs!B15)*(1-0.8)/Inputs!B8))*100))-(Inputs!B6/(Inputs!B7*100)))/(Inputs!B6/(Inputs!B7*100)) -> -0.038943714 | L18: =(((Inputs!B6+Inputs!B14+(Inputs!B34*Inputs!B37*(1-Inputs!B30))-(((Inputs!B16*(1+0.15)*Inputs!B15)*0.9*Inputs!B26*Inputs!B28+(Inputs!B16*(1+0.15)*Inputs!B15)*0.9*Inputs!B27*Inputs!B29)*(1-Inputs!B30)))/((Inputs!B7+((Inputs!B16*(1+0.15)*Inputs!B15)*(1-0.9)/Inputs!B8))*100))-(Inputs!B6/(Inputs!B7*100)))/(Inputs!B6/(Inputs!B7*100)) -> -0.041850902 | M18: =(((Inputs!B6+Inputs!B14+(Inputs!B34*Inputs!B37*(1-Inputs!B30))-(((Inputs!B16*(1+0.15)*Inputs!B15)*1*Inputs!B26*Inputs!B28+(Inputs!B16*(1+0.15)*Inputs!B15)*1*Inputs!B27*Inputs!B29)*(1-Inputs!B30)))/((Inputs!B7+((Inputs!B16*(1+0.15)*Inputs!B15)*(1-1)/Inputs!B8))*100))-(Inputs!B6/(Inputs!B7*100)))/(Inputs!B6/(Inputs!B7*100)) -> -0.044854807
B19: 0.2 | C19: =(((Inputs!B6+Inputs!B14+(Inputs!B34*Inputs!B37*(1-Inputs!B30))-(((Inputs!B16*(1+0.2)*Inputs!B15)*0*Inputs!B26*Inputs!B28+(Inputs!B16*(1+0.2)*Inputs!B15)*0*Inputs!B27*Inputs!B29)*(1-Inputs!B30)))/((Inputs!B7+((Inputs!B16*(1+0.2)*Inputs!B15)*(1-0)/Inputs!B8))*100))-(Inputs!B6/(Inputs!B7*100)))/(Inputs!B6/(Inputs!B7*100)) -> -0.024719044 | D19: =(((Inputs!B6+Inputs!B14+(Inputs!B34*Inputs!B37*(1-Inputs!B30))-(((Inputs!B16*(1+0.2)*Inputs!B15)*0.1*Inputs!B26*Inputs!B28+(Inputs!B16*(1+0.2)*Inputs!B15)*0.1*Inputs!B27*Inputs!B29)*(1-Inputs!B30)))/((Inputs!B7+((Inputs!B16*(1+0.2)*Inputs!B15)*(1-0.1)/Inputs!B8))*100))-(Inputs!B6/(Inputs!B7*100)))/(Inputs!B6/(Inputs!B7*100)) -> -0.027172858 | E19: =(((Inputs!B6+Inputs!B14+(Inputs!B34*Inputs!B37*(1-Inputs!B30))-(((Inputs!B16*(1+0.2)*Inputs!B15)*0.2*Inputs!B26*Inputs!B28+(Inputs!B16*(1+0.2)*Inputs!B15)*0.2*Inputs!B27*Inputs!B29)*(1-Inputs!B30)))/((Inputs!B7+((Inputs!B16*(1+0.2)*Inputs!B15)*(1-0.2)/Inputs!B8))*100))-(Inputs!B6/(Inputs!B7*100)))/(Inputs!B6/(Inputs!B7*100)) -> -0.02970147 | F19: =(((Inputs!B6+Inputs!B14+(Inputs!B34*Inputs!B37*(1-Inputs!B30))-(((Inputs!B16*(1+0.2)*Inputs!B15)*0.3*Inputs!B26*Inputs!B28+(Inputs!B16*(1+0.2)*Inputs!B15)*0.3*Inputs!B27*Inputs!B29)*(1-Inputs!B30)))/((Inputs!B7+((Inputs!B16*(1+0.2)*Inputs!B15)*(1-0.3)/Inputs!B8))*100))-(Inputs!B6/(Inputs!B7*100)))/(Inputs!B6/(Inputs!B7*100)) -> -0.032308353 | G19: =(((Inputs!B6+Inputs!B14+(Inputs!B34*Inputs!B37*(1-Inputs!B30))-(((Inputs!B16*(1+0.2)*Inputs!B15)*0.4*Inputs!B26*Inputs!B28+(Inputs!B16*(1+0.2)*Inputs!B15)*0.4*Inputs!B27*Inputs!B29)*(1-Inputs!B30)))/((Inputs!B7+((Inputs!B16*(1+0.2)*Inputs!B15)*(1-0.4)/Inputs!B8))*100))-(Inputs!B6/(Inputs!B7*100)))/(Inputs!B6/(Inputs!B7*100)) -> -0.034997198 | H19: =(((Inputs!B6+Inputs!B14+(Inputs!B34*Inputs!B37*(1-Inputs!B30))-(((Inputs!B16*(1+0.2)*Inputs!B15)*0.5*Inputs!B26*Inputs!B28+(Inputs!B16*(1+0.2)*Inputs!B15)*0.5*Inputs!B27*Inputs!B29)*(1-Inputs!B30)))/((Inputs!B7+((Inputs!B16*(1+0.2)*Inputs!B15)*(1-0.5)/Inputs!B8))*100))-(Inputs!B6/(Inputs!B7*100)))/(Inputs!B6/(Inputs!B7*100)) -> -0.037771932 | I19: =(((Inputs!B6+Inputs!B14+(Inputs!B34*Inputs!B37*(1-Inputs!B30))-(((Inputs!B16*(1+0.2)*Inputs!B15)*0.6*Inputs!B26*Inputs!B28+(Inputs!B16*(1+0.2)*Inputs!B15)*0.6*Inputs!B27*Inputs!B29)*(1-Inputs!B30)))/((Inputs!B7+((Inputs!B16*(1+0.2)*Inputs!B15)*(1-0.6)/Inputs!B8))*100))-(Inputs!B6/(Inputs!B7*100)))/(Inputs!B6/(Inputs!B7*100)) -> -0.040636738 | J19: =(((Inputs!B6+Inputs!B14+(Inputs!B34*Inputs!B37*(1-Inputs!B30))-(((Inputs!B16*(1+0.2)*Inputs!B15)*0.7*Inputs!B26*Inputs!B28+(Inputs!B16*(1+0.2)*Inputs!B15)*0.7*Inputs!B27*Inputs!B29)*(1-Inputs!B30)))/((Inputs!B7+((Inputs!B16*(1+0.2)*Inputs!B15)*(1-0.7)/Inputs!B8))*100))-(Inputs!B6/(Inputs!B7*100)))/(Inputs!B6/(Inputs!B7*100)) -> -0.043596073 | K19: =(((Inputs!B6+Inputs!B14+(Inputs!B34*Inputs!B37*(1-Inputs!B30))-(((Inputs!B16*(1+0.2)*Inputs!B15)*0.8*Inputs!B26*Inputs!B28+(Inputs!B16*(1+0.2)*Inputs!B15)*0.8*Inputs!B27*Inputs!B29)*(1-Inputs!B30)))/((Inputs!B7+((Inputs!B16*(1+0.2)*Inputs!B15)*(1-0.8)/Inputs!B8))*100))-(Inputs!B6/(Inputs!B7*100)))/(Inputs!B6/(Inputs!B7*100)) -> -0.046654694 | L19: =(((Inputs!B6+Inputs!B14+(Inputs!B34*Inputs!B37*(1-Inputs!B30))-(((Inputs!B16*(1+0.2)*Inputs!B15)*0.9*Inputs!B26*Inputs!B28+(Inputs!B16*(1+0.2)*Inputs!B15)*0.9*Inputs!B27*Inputs!B29)*(1-Inputs!B30)))/((Inputs!B7+((Inputs!B16*(1+0.2)*Inputs!B15)*(1-0.9)/Inputs!B8))*100))-(Inputs!B6/(Inputs!B7*100)))/(Inputs!B6/(Inputs!B7*100)) -> -0.049817685 | M19: =(((Inputs!B6+Inputs!B14+(Inputs!B34*Inputs!B37*(1-Inputs!B30))-(((Inputs!B16*(1+0.2)*Inputs!B15)*1*Inputs!B26*Inputs!B28+(Inputs!B16*(1+0.2)*Inputs!B15)*1*Inputs!B27*Inputs!B29)*(1-Inputs!B30)))/((Inputs!B7+((Inputs!B16*(1+0.2)*Inputs!B15)*(1-1)/Inputs!B8))*100))-(Inputs!B6/(Inputs!B7*100)))/(Inputs!B6/(Inputs!B7*100)) -> -0.053090479
B20: 0.25 | C20: =(((Inputs!B6+Inputs!B14+(Inputs!B34*Inputs!B37*(1-Inputs!B30))-(((Inputs!B16*(1+0.25)*Inputs!B15)*0*Inputs!B26*Inputs!B28+(Inputs!B16*(1+0.25)*Inputs!B15)*0*Inputs!B27*Inputs!B29)*(1-Inputs!B30)))/((Inputs!B7+((Inputs!B16*(1+0.25)*Inputs!B15)*(1-0)/Inputs!B8))*100))-(Inputs!B6/(Inputs!B7*100)))/(Inputs!B6/(Inputs!B7*100)) -> -0.030692522 | D20: =(((Inputs!B6+Inputs!B14+(Inputs!B34*Inputs!B37*(1-Inputs!B30))-(((Inputs!B16*(1+0.25)*Inputs!B15)*0.1*Inputs!B26*Inputs!B28+(Inputs!B16*(1+0.25)*Inputs!B15)*0.1*Inputs!B27*Inputs!B29)*(1-Inputs!B30)))/((Inputs!B7+((Inputs!B16*(1+0.25)*Inputs!B15)*(1-0.1)/Inputs!B8))*100))-(Inputs!B6/(Inputs!B7*100)))/(Inputs!B6/(Inputs!B7*100)) -> -0.033327159 | E20: =(((Inputs!B6+Inputs!B14+(Inputs!B34*Inputs!B37*(1-Inputs!B30))-(((Inputs!B16*(1+0.25)*Inputs!B15)*0.2*Inputs!B26*Inputs!B28+(Inputs!B16*(1+0.25)*Inputs!B15)*0.2*Inputs!B27*Inputs!B29)*(1-Inputs!B30)))/((Inputs!B7+((Inputs!B16*(1+0.25)*Inputs!B15)*(1-0.2)/Inputs!B8))*100))-(Inputs!B6/(Inputs!B7*100)))/(Inputs!B6/(Inputs!B7*100)) -> -0.036045029 | F20: =(((Inputs!B6+Inputs!B14+(Inputs!B34*Inputs!B37*(1-Inputs!B30))-(((Inputs!B16*(1+0.25)*Inputs!B15)*0.3*Inputs!B26*Inputs!B28+(Inputs!B16*(1+0.25)*Inputs!B15)*0.3*Inputs!B27*Inputs!B29)*(1-Inputs!B30)))/((Inputs!B7+((Inputs!B16*(1+0.25)*Inputs!B15)*(1-0.3)/Inputs!B8))*100))-(Inputs!B6/(Inputs!B7*100)))/(Inputs!B6/(Inputs!B7*100)) -> -0.038850139 | G20: =(((Inputs!B6+Inputs!B14+(Inputs!B34*Inputs!B37*(1-Inputs!B30))-(((Inputs!B16*(1+0.25)*Inputs!B15)*0.4*Inputs!B26*Inputs!B28+(Inputs!B16*(1+0.25)*Inputs!B15)*0.4*Inputs!B27*Inputs!B29)*(1-Inputs!B30)))/((Inputs!B7+((Inputs!B16*(1+0.25)*Inputs!B15)*(1-0.4)/Inputs!B8))*100))-(Inputs!B6/(Inputs!B7*100)))/(Inputs!B6/(Inputs!B7*100)) -> -0.041746759 | H20: =(((Inputs!B6+Inputs!B14+(Inputs!B34*Inputs!B37*(1-Inputs!B30))-(((Inputs!B16*(1+0.25)*Inputs!B15)*0.5*Inputs!B26*Inputs!B28+(Inputs!B16*(1+0.25)*Inputs!B15)*0.5*Inputs!B27*Inputs!B29)*(1-Inputs!B30)))/((Inputs!B7+((Inputs!B16*(1+0.25)*Inputs!B15)*(1-0.5)/Inputs!B8))*100))-(Inputs!B6/(Inputs!B7*100)))/(Inputs!B6/(Inputs!B7*100)) -> -0.044739441 | I20: =(((Inputs!B6+Inputs!B14+(Inputs!B34*Inputs!B37*(1-Inputs!B30))-(((Inputs!B16*(1+0.25)*Inputs!B15)*0.6*Inputs!B26*Inputs!B28+(Inputs!B16*(1+0.25)*Inputs!B15)*0.6*Inputs!B27*Inputs!B29)*(1-Inputs!B30)))/((Inputs!B7+((Inputs!B16*(1+0.25)*Inputs!B15)*(1-0.6)/Inputs!B8))*100))-(Inputs!B6/(Inputs!B7*100)))/(Inputs!B6/(Inputs!B7*100)) -> -0.047833044 | J20: =(((Inputs!B6+Inputs!B14+(Inputs!B34*Inputs!B37*(1-Inputs!B30))-(((Inputs!B16*(1+0.25)*Inputs!B15)*0.7*Inputs!B26*Inputs!B28+(Inputs!B16*(1+0.25)*Inputs!B15)*0.7*Inputs!B27*Inputs!B29)*(1-Inputs!B30)))/((Inputs!B7+((Inputs!B16*(1+0.25)*Inputs!B15)*(1-0.7)/Inputs!B8))*100))-(Inputs!B6/(Inputs!B7*100)))/(Inputs!B6/(Inputs!B7*100)) -> -0.051032761 | K20: =(((Inputs!B6+Inputs!B14+(Inputs!B34*Inputs!B37*(1-Inputs!B30))-(((Inputs!B16*(1+0.25)*Inputs!B15)*0.8*Inputs!B26*Inputs!B28+(Inputs!B16*(1+0.25)*Inputs!B15)*0.8*Inputs!B27*Inputs!B29)*(1-Inputs!B30)))/((Inputs!B7+((Inputs!B16*(1+0.25)*Inputs!B15)*(1-0.8)/Inputs!B8))*100))-(Inputs!B6/(Inputs!B7*100)))/(Inputs!B6/(Inputs!B7*100)) -> -0.054344146 | L20: =(((Inputs!B6+Inputs!B14+(Inputs!B34*Inputs!B37*(1-Inputs!B30))-(((Inputs!B16*(1+0.25)*Inputs!B15)*0.9*Inputs!B26*Inputs!B28+(Inputs!B16*(1+0.25)*Inputs!B15)*0.9*Inputs!B27*Inputs!B29)*(1-Inputs!B30)))/((Inputs!B7+((Inputs!B16*(1+0.25)*Inputs!B15)*(1-0.9)/Inputs!B8))*100))-(Inputs!B6/(Inputs!B7*100)))/(Inputs!B6/(Inputs!B7*100)) -> -0.057773149 | M20: =(((Inputs!B6+Inputs!B14+(Inputs!B34*Inputs!B37*(1-Inputs!B30))-(((Inputs!B16*(1+0.25)*Inputs!B15)*1*Inputs!B26*Inputs!B28+(Inputs!B16*(1+0.25)*Inputs!B15)*1*Inputs!B27*Inputs!B29)*(1-Inputs!B30)))/((Inputs!B7+((Inputs!B16*(1+0.25)*Inputs!B15)*(1-1)/Inputs!B8))*100))-(Inputs!B6/(Inputs!B7*100)))/(Inputs!B6/(Inputs!B7*100)) -> -0.06132615
B21: 0.3 | C21: =(((Inputs!B6+Inputs!B14+(Inputs!B34*Inputs!B37*(1-Inputs!B30))-(((Inputs!B16*(1+0.3)*Inputs!B15)*0*Inputs!B26*Inputs!B28+(Inputs!B16*(1+0.3)*Inputs!B15)*0*Inputs!B27*Inputs!B29)*(1-Inputs!B30)))/((Inputs!B7+((Inputs!B16*(1+0.3)*Inputs!B15)*(1-0)/Inputs!B8))*100))-(Inputs!B6/(Inputs!B7*100)))/(Inputs!B6/(Inputs!B7*100)) -> -0.036593272 | D21: =(((Inputs!B6+Inputs!B14+(Inputs!B34*Inputs!B37*(1-Inputs!B30))-(((Inputs!B16*(1+0.3)*Inputs!B15)*0.1*Inputs!B26*Inputs!B28+(Inputs!B16*(1+0.3)*Inputs!B15)*0.1*Inputs!B27*Inputs!B29)*(1-Inputs!B30)))/((Inputs!B7+((Inputs!B16*(1+0.3)*Inputs!B15)*(1-0.1)/Inputs!B8))*100))-(Inputs!B6/(Inputs!B7*100)))/(Inputs!B6/(Inputs!B7*100)) -> -0.039412938 | E21: =(((Inputs!B6+Inputs!B14+(Inputs!B34*Inputs!B37*(1-Inputs!B30))-(((Inputs!B16*(1+0.3)*Inputs!B15)*0.2*Inputs!B26*Inputs!B28+(Inputs!B16*(1+0.3)*Inputs!B15)*0.2*Inputs!B27*Inputs!B29)*(1-Inputs!B30)))/((Inputs!B7+((Inputs!B16*(1+0.3)*Inputs!B15)*(1-0.2)/Inputs!B8))*100))-(Inputs!B6/(Inputs!B7*100)))/(Inputs!B6/(Inputs!B7*100)) -> -0.04232478 | F21: =(((Inputs!B6+Inputs!B14+(Inputs!B34*Inputs!B37*(1-Inputs!B30))-(((Inputs!B16*(1+0.3)*Inputs!B15)*0.3*Inputs!B26*Inputs!B28+(Inputs!B16*(1+0.3)*Inputs!B15)*0.3*Inputs!B27*Inputs!B29)*(1-Inputs!B30)))/((Inputs!B7+((Inputs!B16*(1+0.3)*Inputs!B15)*(1-0.3)/Inputs!B8))*100))-(Inputs!B6/(Inputs!B7*100)))/(Inputs!B6/(Inputs!B7*100)) -> -0.045333393 | G21: =(((Inputs!B6+Inputs!B14+(Inputs!B34*Inputs!B37*(1-Inputs!B30))-(((Inputs!B16*(1+0.3)*Inputs!B15)*0.4*Inputs!B26*Inputs!B28+(Inputs!B16*(1+0.3)*Inputs!B15)*0.4*Inputs!B27*Inputs!B29)*(1-Inputs!B30)))/((Inputs!B7+((Inputs!B16*(1+0.3)*Inputs!B15)*(1-0.4)/Inputs!B8))*100))-(Inputs!B6/(Inputs!B7*100)))/(Inputs!B6/(Inputs!B7*100)) -> -0.048443682 | H21: =(((Inputs!B6+Inputs!B14+(Inputs!B34*Inputs!B37*(1-Inputs!B30))-(((Inputs!B16*(1+0.3)*Inputs!B15)*0.5*Inputs!B26*Inputs!B28+(Inputs!B16*(1+0.3)*Inputs!B15)*0.5*Inputs!B27*Inputs!B29)*(1-Inputs!B30)))/((Inputs!B7+((Inputs!B16*(1+0.3)*Inputs!B15)*(1-0.5)/Inputs!B8))*100))-(Inputs!B6/(Inputs!B7*100)))/(Inputs!B6/(Inputs!B7*100)) -> -0.05166089 | I21: =(((Inputs!B6+Inputs!B14+(Inputs!B34*Inputs!B37*(1-Inputs!B30))-(((Inputs!B16*(1+0.3)*Inputs!B15)*0.6*Inputs!B26*Inputs!B28+(Inputs!B16*(1+0.3)*Inputs!B15)*0.6*Inputs!B27*Inputs!B29)*(1-Inputs!B30)))/((Inputs!B7+((Inputs!B16*(1+0.3)*Inputs!B15)*(1-0.6)/Inputs!B8))*100))-(Inputs!B6/(Inputs!B7*100)))/(Inputs!B6/(Inputs!B7*100)) -> -0.054990627 | J21: =(((Inputs!B6+Inputs!B14+(Inputs!B34*Inputs!B37*(1-Inputs!B30))-(((Inputs!B16*(1+0.3)*Inputs!B15)*0.7*Inputs!B26*Inputs!B28+(Inputs!B16*(1+0.3)*Inputs!B15)*0.7*Inputs!B27*Inputs!B29)*(1-Inputs!B30)))/((Inputs!B7+((Inputs!B16*(1+0.3)*Inputs!B15)*(1-0.7)/Inputs!B8))*100))-(Inputs!B6/(Inputs!B7*100)))/(Inputs!B6/(Inputs!B7*100)) -> -0.058438902 | K21: =(((Inputs!B6+Inputs!B14+(Inputs!B34*Inputs!B37*(1-Inputs!B30))-(((Inputs!B16*(1+0.3)*Inputs!B15)*0.8*Inputs!B26*Inputs!B28+(Inputs!B16*(1+0.3)*Inputs!B15)*0.8*Inputs!B27*Inputs!B29)*(1-Inputs!B30)))/((Inputs!B7+((Inputs!B16*(1+0.3)*Inputs!B15)*(1-0.8)/Inputs!B8))*100))-(Inputs!B6/(Inputs!B7*100)))/(Inputs!B6/(Inputs!B7*100)) -> -0.062012159 | L21: =(((Inputs!B6+Inputs!B14+(Inputs!B34*Inputs!B37*(1-Inputs!B30))-(((Inputs!B16*(1+0.3)*Inputs!B15)*0.9*Inputs!B26*Inputs!B28+(Inputs!B16*(1+0.3)*Inputs!B15)*0.9*Inputs!B27*Inputs!B29)*(1-Inputs!B30)))/((Inputs!B7+((Inputs!B16*(1+0.3)*Inputs!B15)*(1-0.9)/Inputs!B8))*100))-(Inputs!B6/(Inputs!B7*100)))/(Inputs!B6/(Inputs!B7*100)) -> -0.065717318 | M21: =(((Inputs!B6+Inputs!B14+(Inputs!B34*Inputs!B37*(1-Inputs!B30))-(((Inputs!B16*(1+0.3)*Inputs!B15)*1*Inputs!B26*Inputs!B28+(Inputs!B16*(1+0.3)*Inputs!B15)*1*Inputs!B27*Inputs!B29)*(1-Inputs!B30)))/((Inputs!B7+((Inputs!B16*(1+0.3)*Inputs!B15)*(1-1)/Inputs!B8))*100))-(Inputs!B6/(Inputs!B7*100)))/(Inputs!B6/(Inputs!B7*100)) -> -0.069561822
B22: 0.35 | C22: =(((Inputs!B6+Inputs!B14+(Inputs!B34*Inputs!B37*(1-Inputs!B30))-(((Inputs!B16*(1+0.35)*Inputs!B15)*0*Inputs!B26*Inputs!B28+(Inputs!B16*(1+0.35)*Inputs!B15)*0*Inputs!B27*Inputs!B29)*(1-Inputs!B30)))/((Inputs!B7+((Inputs!B16*(1+0.35)*Inputs!B15)*(1-0)/Inputs!B8))*100))-(Inputs!B6/(Inputs!B7*100)))/(Inputs!B6/(Inputs!B7*100)) -> -0.042422614 | D22: =(((Inputs!B6+Inputs!B14+(Inputs!B34*Inputs!B37*(1-Inputs!B30))-(((Inputs!B16*(1+0.35)*Inputs!B15)*0.1*Inputs!B26*Inputs!B28+(Inputs!B16*(1+0.35)*Inputs!B15)*0.1*Inputs!B27*Inputs!B29)*(1-Inputs!B30)))/((Inputs!B7+((Inputs!B16*(1+0.35)*Inputs!B15)*(1-0.1)/Inputs!B8))*100))-(Inputs!B6/(Inputs!B7*100)))/(Inputs!B6/(Inputs!B7*100)) -> -0.045431334 | E22: =(((Inputs!B6+Inputs!B14+(Inputs!B34*Inputs!B37*(1-Inputs!B30))-(((Inputs!B16*(1+0.35)*Inputs!B15)*0.2*Inputs!B26*Inputs!B28+(Inputs!B16*(1+0.35)*Inputs!B15)*0.2*Inputs!B27*Inputs!B29)*(1-Inputs!B30)))/((Inputs!B7+((Inputs!B16*(1+0.35)*Inputs!B15)*(1-0.2)/Inputs!B8))*100))-(Inputs!B6/(Inputs!B7*100)))/(Inputs!B6/(Inputs!B7*100)) -> -0.048541683 | F22: =(((Inputs!B6+Inputs!B14+(Inputs!B34*Inputs!B37*(1-Inputs!B30))-(((Inputs!B16*(1+0.35)*Inputs!B15)*0.3*Inputs!B26*Inputs!B28+(Inputs!B16*(1+0.35)*Inputs!B15)*0.3*Inputs!B27*Inputs!B29)*(1-Inputs!B30)))/((Inputs!B7+((Inputs!B16*(1+0.35)*Inputs!B15)*(1-0.3)/Inputs!B8))*100))-(Inputs!B6/(Inputs!B7*100)))/(Inputs!B6/(Inputs!B7*100)) -> -0.051758896 | G22: =(((Inputs!B6+Inputs!B14+(Inputs!B34*Inputs!B37*(1-Inputs!B30))-(((Inputs!B16*(1+0.35)*Inputs!B15)*0.4*Inputs!B26*Inputs!B28+(Inputs!B16*(1+0.35)*Inputs!B15)*0.4*Inputs!B27*Inputs!B29)*(1-Inputs!B30)))/((Inputs!B7+((Inputs!B16*(1+0.35)*Inputs!B15)*(1-0.4)/Inputs!B8))*100))-(Inputs!B6/(Inputs!B7*100)))/(Inputs!B6/(Inputs!B7*100)) -> -0.055088579 | H22: =(((Inputs!B6+Inputs!B14+(Inputs!B34*Inputs!B37*(1-Inputs!B30))-(((Inputs!B16*(1+0.35)*Inputs!B15)*0.5*Inputs!B26*Inputs!B28+(Inputs!B16*(1+0.35)*Inputs!B15)*0.5*Inputs!B27*Inputs!B29)*(1-Inputs!B30)))/((Inputs!B7+((Inputs!B16*(1+0.35)*Inputs!B15)*(1-0.5)/Inputs!B8))*100))-(Inputs!B6/(Inputs!B7*100)))/(Inputs!B6/(Inputs!B7*100)) -> -0.058536734 | I22: =(((Inputs!B6+Inputs!B14+(Inputs!B34*Inputs!B37*(1-Inputs!B30))-(((Inputs!B16*(1+0.35)*Inputs!B15)*0.6*Inputs!B26*Inputs!B28+(Inputs!B16*(1+0.35)*Inputs!B15)*0.6*Inputs!B27*Inputs!B29)*(1-Inputs!B30)))/((Inputs!B7+((Inputs!B16*(1+0.35)*Inputs!B15)*(1-0.6)/Inputs!B8))*100))-(Inputs!B6/(Inputs!B7*100)))/(Inputs!B6/(Inputs!B7*100)) -> -0.062109798 | J22: =(((Inputs!B6+Inputs!B14+(Inputs!B34*Inputs!B37*(1-Inputs!B30))-(((Inputs!B16*(1+0.35)*Inputs!B15)*0.7*Inputs!B26*Inputs!B28+(Inputs!B16*(1+0.35)*Inputs!B15)*0.7*Inputs!B27*Inputs!B29)*(1-Inputs!B30)))/((Inputs!B7+((Inputs!B16*(1+0.35)*Inputs!B15)*(1-0.7)/Inputs!B8))*100))-(Inputs!B6/(Inputs!B7*100)))/(Inputs!B6/(Inputs!B7*100)) -> -0.065814683 | K22: =(((Inputs!B6+Inputs!B14+(Inputs!B34*Inputs!B37*(1-Inputs!B30))-(((Inputs!B16*(1+0.35)*Inputs!B15)*0.8*Inputs!B26*Inputs!B28+(Inputs!B16*(1+0.35)*Inputs!B15)*0.8*Inputs!B27*Inputs!B29)*(1-Inputs!B30)))/((Inputs!B7+((Inputs!B16*(1+0.35)*Inputs!B15)*(1-0.8)/Inputs!B8))*100))-(Inputs!B6/(Inputs!B7*100)))/(Inputs!B6/(Inputs!B7*100)) -> -0.069658822 | L22: =(((Inputs!B6+Inputs!B14+(Inputs!B34*Inputs!B37*(1-Inputs!B30))-(((Inputs!B16*(1+0.35)*Inputs!B15)*0.9*Inputs!B26*Inputs!B28+(Inputs!B16*(1+0.35)*Inputs!B15)*0.9*Inputs!B27*Inputs!B29)*(1-Inputs!B30)))/((Inputs!B7+((Inputs!B16*(1+0.35)*Inputs!B15)*(1-0.9)/Inputs!B8))*100))-(Inputs!B6/(Inputs!B7*100)))/(Inputs!B6/(Inputs!B7*100)) -> -0.073650217 | M22: =(((Inputs!B6+Inputs!B14+(Inputs!B34*Inputs!B37*(1-Inputs!B30))-(((Inputs!B16*(1+0.35)*Inputs!B15)*1*Inputs!B26*Inputs!B28+(Inputs!B16*(1+0.35)*Inputs!B15)*1*Inputs!B27*Inputs!B29)*(1-Inputs!B30)))/((Inputs!B7+((Inputs!B16*(1+0.35)*Inputs!B15)*(1-1)/Inputs!B8))*100))-(Inputs!B6/(Inputs!B7*100)))/(Inputs!B6/(Inputs!B7*100)) -> -0.077797493
